Workbook

Sheet Hitters
H1: 1.2 | I1: 2 | J1: 1 | K1: 1.2 | L1: 1.6 | M1: 1 | N1: 0.2 | O1: 0.1 | W1: 1 | X1: 1 | Y1: 1 | Z1: 1 | AB1: 0.8 | AC1: 0.2 | AD1: 1 | AE1: 0.1 | AF1: 0.1 | AG1: 0.1 | AI1: (-2*10^-6)*A1^3+0.00032*A1^2-0.0021*A1
X2: 0.2 | Y2: 0.5 | Z2: 0.3 | AA2: 1
H3: 2.5 | M3: 0.6 | W3: 2 | AB3: 1 | AD3: 0.6 | AI3: 2.5 | AJ3: 0.6 | AK3: 2 | AL3: 1 | AM3: 0.6
H5: 100 | I5: 100 | J5: 100 | K5: 100 | L5: 100 | M5: 100 | N5: 100 | O5: 100 | P5: 100 | W5: 100 | X5: 100 | Y5: 100 | Z5: 100 | AA5: 100 | AB5: 100 | AC5: 100 | AD5: 100 | AE5: 100 | AF5: 100 | AG5: 100 | AI5: =H$1*((-0.000002)*H5^3+0.00032*H5^2+(-0.0021)*H5)+I$1*((-0.000002)*I5^3+0.00032*I5^2+(-0.0021)*I5)+J$1*((-0.000002)*J5^3+0.00032*J5^2+(-0.0021)*J5)+K$1*((-0.000002)*K5^3+0.00032*K5^2+(-0.0021)*K5)+L$1*((-0.000002)*L5^3+0.00032*L5^2+(-0.0021)*L5) -> 6.93 | AJ5: =M$1*((-0.000002)*M5^3+0.00032*M5^2+(-0.0021)*M5)+N$1*((-0.000002)*N5^3+0.00032*N5^2+(-0.0021)*N5)+O$1*((-0.000002)*O5^3+0.00032*O5^2+(-0.0021)*O5) -> 1.287 | AK5: =IF(AA5>50,W$1*((-0.000002)*W5^3+0.00032*W5^2+(-0.0021)*W5)+X$1*((-0.000002)*X5^3+0.00032*X5^2+(-0.0021)*X5)+Y$1*((-0.000002)*Y5^3+0.00032*Y5^2+(-0.0021)*Y5)+Z$1*((-0.000002)*Z5^3+0.00032*Z5^2+(-0.0021)*Z5),X$2*((-0.000002)*X5^3+0.00032*X5^2+(-0.0021)*X5)+Y$2*((-0.000002)*Y5^3+0.00032*Y5^2+(-0.0021)*Y5)+Z$2*((-0.000002)*Z5^3+0.00032*Z5^2+(-0.0021)*Z5)+AA$2*((-0.000002)*AA5^3+0.00032*AA5^2+(-0.0021)*AA5)) -> 3.96 | AL5: =AB$1*((-0.000002)*AB5^3+0.00032*AB5^2+(-0.0021)*AB5)+AC$1*((-0.000002)*AC5^3+0.00032*AC5^2+(-0.0021)*AC5) -> 0.99 | AM5: =AD$1*((-0.000002)*AD5^3+0.00032*AD5^2+(-0.0021)*AD5)+AE$1*((-0.000002)*AE5^3+0.00032*AE5^2+(-0.0021)*AE5)+AF$1*((-0.000002)*AF5^3+0.00032*AF5^2+(-0.0021)*AF5)+AG$1*((-0.000002)*AG5^3+0.00032*AG5^2+(-0.0021)*AG5) -> 1.287
A6: Overall Projection | B6: Rnk | C6: Player | D6: Pos | E6: B | F6: T | G6: Age | H6: Contact | I6: Power | J6: vs L | K6: vs R | L6: Batting Eye | M6: Baserunning | N6: Bunt | O6: Push/Pull | P6: Overall | Q6: Rank | R6: Player | S6: Pos | T6: B | U6: T | V6: Age | W6: Range | X6: Glove | Y6: Arm Strength | Z6: Arm Accuracy | AA6: Pitch Calling | AB6: Durability | AC6: Health | AD6: Speed | AE6: Patience | AF6: Temper | AG6: Makeup | AH6: Overall | AI6: hitting | AJ6: baserunning | AK6: fielding | AL6: durability | AM6: intangibles
A7: =IFERROR((AI7*AI$3+AJ7*AJ$3+AK7*AK$3+AL7*AL$3+AM7*AM$3)*100/(AI$5*AI$3+AJ$5*AJ$3+AK$5*AK$3+AL$5*AL$3+AM$5*AM$3),0) -> 75.250027 | B7: 1 | C7: Lozada, Marshall | D7: 3B | E7: R | F7: R | G7: 18 | H7: 88 | I7: 52 | J7: 61 | K7: 77 | L7: 72 | M7: 88 | N7: 42 | O7: 62 | P7: 88 | Q7: 1 | R7: Lozada, Marshall | S7: 3B | T7: R | U7: R | V7: 18 | W7: 63 | X7: 66 | Y7: 100 | Z7: 87 | AA7: 0 | AB7: 92 | AC7: 100 | AD7: 89 | AE7: 42 | AF7: 46 | AG7: 64 | AH7: 88 | AI7: =H$1*((-0.000002)*H7^3+0.00032*H7^2+(-0.0021)*H7)+I$1*((-0.000002)*I7^3+0.00032*I7^2+(-0.0021)*I7)+J$1*((-0.000002)*J7^3+0.00032*J7^2+(-0.0021)*J7)+K$1*((-0.000002)*K7^3+0.00032*K7^2+(-0.0021)*K7)+L$1*((-0.000002)*L7^3+0.00032*L7^2+(-0.0021)*L7) -> 4.8797004 | AJ7: =M$1*((-0.000002)*M7^3+0.00032*M7^2+(-0.0021)*M7)+N$1*((-0.000002)*N7^3+0.00032*N7^2+(-0.0021)*N7)+O$1*((-0.000002)*O7^3+0.00032*O7^2+(-0.0021)*O7) -> 1.0582792 | AK7: =IF(AA7<50,W$1*((-0.000002)*W7^3+0.00032*W7^2+(-0.0021)*W7)+X$1*((-0.000002)*X7^3+0.00032*X7^2+(-0.0021)*X7)+Y$1*((-0.000002)*Y7^3+0.00032*Y7^2+(-0.0021)*Y7)+Z$1*((-0.000002)*Z7^3+0.00032*Z7^2+(-0.0021)*Z7),X$2*((-0.000002)*X7^3+0.00032*X7^2+(-0.0021)*X7)+Y$2*((-0.000002)*Y7^3+0.00032*Y7^2+(-0.0021)*Y7)+Z$2*((-0.000002)*Z7^3+0.00032*Z7^2+(-0.0021)*Z7)+AA$2*((-0.000002)*AA7^3+0.00032*AA7^2+(-0.0021)*AA7)) -> 3.230388 | AL7: =AB$1*((-0.000002)*AB7^3+0.00032*AB7^2+(-0.0021)*AB7)+AC$1*((-0.000002)*AC7^3+0.00032*AC7^2+(-0.0021)*AC7) -> 0.9643232 | AM7: =AD$1*((-0.000002)*AD7^3+0.00032*AD7^2+(-0.0021)*AD7)+AE$1*((-0.000002)*AE7^3+0.00032*AE7^2+(-0.0021)*AE7)+AF$1*((-0.000002)*AF7^3+0.00032*AF7^2+(-0.0021)*AF7)+AG$1*((-0.000002)*AG7^3+0.00032*AG7^2+(-0.0021)*AG7) -> 1.0744804
A8: =IFERROR((AI8*AI$3+AJ8*AJ$3+AK8*AK$3+AL8*AL$3+AM8*AM$3)*100/(AI$5*AI$3+AJ$5*AJ$3+AK$5*AK$3+AL$5*AL$3+AM$5*AM$3),0) -> 83.537811 | B8: 2 | C8: Romero, Jerome | D8: SS | E8: R | F8: R | G8: 18 | H8: 82 | I8: 86 | J8: 84 | K8: 45 | L8: 82 | M8: 62 | N8: 47 | O8: 73 | P8: 89 | Q8: 2 | R8: Romero, Jerome | S8: SS | T8: R | U8: R | V8: 18 | W8: 95 | X8: 100 | Y8: 77 | Z8: 74 | AA8: 4 | AB8: 78 | AC8: 62 | AD8: 100 | AE8: 75 | AF8: 63 | AG8: 98 | AH8: 89 | AI8: =H$1*((-0.000002)*H8^3+0.00032*H8^2+(-0.0021)*H8)+I$1*((-0.000002)*I8^3+0.00032*I8^2+(-0.0021)*I8)+J$1*((-0.000002)*J8^3+0.00032*J8^2+(-0.0021)*J8)+K$1*((-0.000002)*K8^3+0.00032*K8^2+(-0.0021)*K8)+L$1*((-0.000002)*L8^3+0.00032*L8^2+(-0.0021)*L8) -> 5.6245112 | AJ8: =M$1*((-0.000002)*M8^3+0.00032*M8^2+(-0.0021)*M8)+N$1*((-0.000002)*N8^3+0.00032*N8^2+(-0.0021)*N8)+O$1*((-0.000002)*O8^3+0.00032*O8^2+(-0.0021)*O8) -> 0.7807254 | AK8: =IF(AA8<50,W$1*((-0.000002)*W8^3+0.00032*W8^2+(-0.0021)*W8)+X$1*((-0.000002)*X8^3+0.00032*X8^2+(-0.0021)*X8)+Y$1*((-0.000002)*Y8^3+0.00032*Y8^2+(-0.0021)*Y8)+Z$1*((-0.000002)*Z8^3+0.00032*Z8^2+(-0.0021)*Z8),X$2*((-0.000002)*X8^3+0.00032*X8^2+(-0.0021)*X8)+Y$2*((-0.000002)*Y8^3+0.00032*Y8^2+(-0.0021)*Y8)+Z$2*((-0.000002)*Z8^3+0.00032*Z8^2+(-0.0021)*Z8)+AA$2*((-0.000002)*AA8^3+0.00032*AA8^2+(-0.0021)*AA8)) -> 3.572736 | AL8: =AB$1*((-0.000002)*AB8^3+0.00032*AB8^2+(-0.0021)*AB8)+AC$1*((-0.000002)*AC8^3+0.00032*AC8^2+(-0.0021)*AC8) -> 0.7918256 | AM8: =AD$1*((-0.000002)*AD8^3+0.00032*AD8^2+(-0.0021)*AD8)+AE$1*((-0.000002)*AE8^3+0.00032*AE8^2+(-0.0021)*AE8)+AF$1*((-0.000002)*AF8^3+0.00032*AF8^2+(-0.0021)*AF8)+AG$1*((-0.000002)*AG8^3+0.00032*AG8^2+(-0.0021)*AG8) -> 1.2321532
A9: =IFERROR((AI9*AI$3+AJ9*AJ$3+AK9*AK$3+AL9*AL$3+AM9*AM$3)*100/(AI$5*AI$3+AJ$5*AJ$3+AK$5*AK$3+AL$5*AL$3+AM$5*AM$3),0) -> 69.832543 | B9: 3 | C9: Cunnane, John | D9: RF | E9: R | F9: R | G9: 18 | H9: 99 | I9: 92 | J9: 55 | K9: 40 | L9: 77 | M9: 43 | N9: 52 | O9: 33 | P9: 81 | Q9: 3 | R9: Cunnane, John | S9: RF | T9: R | U9: R | V9: 18 | W9: 55 | X9: 50 | Y9: 61 | Z9: 67 | AA9: 0 | AB9: 92 | AC9: 86 | AD9: 51 | AE9: 37 | AF9: 88 | AG9: 78 | AH9: 81 | AI9: =H$1*((-0.000002)*H9^3+0.00032*H9^2+(-0.0021)*H9)+I$1*((-0.000002)*I9^3+0.00032*I9^2+(-0.0021)*I9)+J$1*((-0.000002)*J9^3+0.00032*J9^2+(-0.0021)*J9)+K$1*((-0.000002)*K9^3+0.00032*K9^2+(-0.0021)*K9)+L$1*((-0.000002)*L9^3+0.00032*L9^2+(-0.0021)*L9) -> 5.2969668 | AJ9: =M$1*((-0.000002)*M9^3+0.00032*M9^2+(-0.0021)*M9)+N$1*((-0.000002)*N9^3+0.00032*N9^2+(-0.0021)*N9)+O$1*((-0.000002)*O9^3+0.00032*O9^2+(-0.0021)*O9) -> 0.4580694 | AK9: =IF(AA9<50,W$1*((-0.000002)*W9^3+0.00032*W9^2+(-0.0021)*W9)+X$1*((-0.000002)*X9^3+0.00032*X9^2+(-0.0021)*X9)+Y$1*((-0.000002)*Y9^3+0.00032*Y9^2+(-0.0021)*Y9)+Z$1*((-0.000002)*Z9^3+0.00032*Z9^2+(-0.0021)*Z9),X$2*((-0.000002)*X9^3+0.00032*X9^2+(-0.0021)*X9)+Y$2*((-0.000002)*Y9^3+0.00032*Y9^2+(-0.0021)*Y9)+Z$2*((-0.000002)*Z9^3+0.00032*Z9^2+(-0.0021)*Z9)+AA$2*((-0.000002)*AA9^3+0.00032*AA9^2+(-0.0021)*AA9)) -> 2.267662 | AL9: =AB$1*((-0.000002)*AB9^3+0.00032*AB9^2+(-0.0021)*AB9)+AC$1*((-0.000002)*AC9^3+0.00032*AC9^2+(-0.0021)*AC9) -> 0.9491248 | AM9: =AD$1*((-0.000002)*AD9^3+0.00032*AD9^2+(-0.0021)*AD9)+AE$1*((-0.000002)*AE9^3+0.00032*AE9^2+(-0.0021)*AE9)+AF$1*((-0.000002)*AF9^3+0.00032*AF9^2+(-0.0021)*AF9)+AG$1*((-0.000002)*AG9^3+0.00032*AG9^2+(-0.0021)*AG9) -> 0.6622566
A10: =IFERROR((AI10*AI$3+AJ10*AJ$3+AK10*AK$3+AL10*AL$3+AM10*AM$3)*100/(AI$5*AI$3+AJ$5*AJ$3+AK$5*AK$3+AL$5*AL$3+AM$5*AM$3),0) -> 67.417684 | B10: 5 | C10: Bailey, Alexander | D10: 1B | E10: R | F10: R | G10: 18 | H10: 59 | I10: 76 | J10: 66 | K10: 75 | L10: 71 | M10: 51 | N10: 44 | O10: 39 | P10: 74 | Q10: 5 | R10: Bailey, Alexander | S10: 1B | T10: R | U10: R | V10: 18 | W10: 69 | X10: 79 | Y10: 32 | Z10: 42 | AA10: 14 | AB10: 80 | AC10: 67 | AD10: 61 | AE10: 60 | AF10: 90 | AG10: 78 | AH10: 74 | AI10: =H$1*((-0.000002)*H10^3+0.00032*H10^2+(-0.0021)*H10)+I$1*((-0.000002)*I10^3+0.00032*I10^2+(-0.0021)*I10)+J$1*((-0.000002)*J10^3+0.00032*J10^2+(-0.0021)*J10)+K$1*((-0.000002)*K10^3+0.00032*K10^2+(-0.0021)*K10)+L$1*((-0.000002)*L10^3+0.00032*L10^2+(-0.0021)*L10) -> 5.1525952 | AJ10: =M$1*((-0.000002)*M10^3+0.00032*M10^2+(-0.0021)*M10)+N$1*((-0.000002)*N10^3+0.00032*N10^2+(-0.0021)*N10)+O$1*((-0.000002)*O10^3+0.00032*O10^2+(-0.0021)*O10) -> 0.5598866 | AK10: =IF(AA10<50,W$1*((-0.000002)*W10^3+0.00032*W10^2+(-0.0021)*W10)+X$1*((-0.000002)*X10^3+0.00032*X10^2+(-0.0021)*X10)+Y$1*((-0.000002)*Y10^3+0.00032*Y10^2+(-0.0021)*Y10)+Z$1*((-0.000002)*Z10^3+0.00032*Z10^2+(-0.0021)*Z10),X$2*((-0.000002)*X10^3+0.00032*X10^2+(-0.0021)*X10)+Y$2*((-0.000002)*Y10^3+0.00032*Y10^2+(-0.0021)*Y10)+Z$2*((-0.000002)*Z10^3+0.00032*Z10^2+(-0.0021)*Z10)+AA$2*((-0.000002)*AA10^3+0.00032*AA10^2+(-0.0021)*AA10)) -> 2.089792 | AL10: =AB$1*((-0.000002)*AB10^3+0.00032*AB10^2+(-0.0021)*AB10)+AC$1*((-0.000002)*AC10^3+0.00032*AC10^2+(-0.0021)*AC10) -> 0.8236508 | AM10: =AD$1*((-0.000002)*AD10^3+0.00032*AD10^2+(-0.0021)*AD10)+AE$1*((-0.000002)*AE10^3+0.00032*AE10^2+(-0.0021)*AE10)+AF$1*((-0.000002)*AF10^3+0.00032*AF10^2+(-0.0021)*AF10)+AG$1*((-0.000002)*AG10^3+0.00032*AG10^2+(-0.0021)*AG10) -> 0.8459556
A11: =IFERROR((AI11*AI$3+AJ11*AJ$3+AK11*AK$3+AL11*AL$3+AM11*AM$3)*100/(AI$5*AI$3+AJ$5*AJ$3+AK$5*AK$3+AL$5*AL$3+AM$5*AM$3),0) -> 74.307689 | B11: 7 | C11: Patrick, Alex | D11: 3B | E11: R | F11: R | G11: 18 | H11: 37 | I11: 95 | J11: 80 | K11: 68 | L11: 78 | M11: 40 | N11: 45 | O11: 36 | P11: 80 | Q11: 7 | R11: Patrick, Alex | S11: 3B | T11: R | U11: R | V11: 18 | W11: 60 | X11: 58 | Y11: 94 | Z11: 74 | AA11: 34 | AB11: 78 | AC11: 100 | AD11: 60 | AE11: 67 | AF11: 32 | AG11: 85 | AH11: 80 | AI11: =H$1*((-0.000002)*H11^3+0.00032*H11^2+(-0.0021)*H11)+I$1*((-0.000002)*I11^3+0.00032*I11^2+(-0.0021)*I11)+J$1*((-0.000002)*J11^3+0.00032*J11^2+(-0.0021)*J11)+K$1*((-0.000002)*K11^3+0.00032*K11^2+(-0.0021)*K11)+L$1*((-0.000002)*L11^3+0.00032*L11^2+(-0.0021)*L11) -> 5.2983696 | AJ11: =M$1*((-0.000002)*M11^3+0.00032*M11^2+(-0.0021)*M11)+N$1*((-0.000002)*N11^3+0.00032*N11^2+(-0.0021)*N11)+O$1*((-0.000002)*O11^3+0.00032*O11^2+(-0.0021)*O11) -> 0.3988308 | AK11: =IF(AA11<50,W$1*((-0.000002)*W11^3+0.00032*W11^2+(-0.0021)*W11)+X$1*((-0.000002)*X11^3+0.00032*X11^2+(-0.0021)*X11)+Y$1*((-0.000002)*Y11^3+0.00032*Y11^2+(-0.0021)*Y11)+Z$1*((-0.000002)*Z11^3+0.00032*Z11^2+(-0.0021)*Z11),X$2*((-0.000002)*X11^3+0.00032*X11^2+(-0.0021)*X11)+Y$2*((-0.000002)*Y11^3+0.00032*Y11^2+(-0.0021)*Y11)+Z$2*((-0.000002)*Z11^3+0.00032*Z11^2+(-0.0021)*Z11)+AA$2*((-0.000002)*AA11^3+0.00032*AA11^2+(-0.0021)*AA11)) -> 2.91388 | AL11: =AB$1*((-0.000002)*AB11^3+0.00032*AB11^2+(-0.0021)*AB11)+AC$1*((-0.000002)*AC11^3+0.00032*AC11^2+(-0.0021)*AC11) -> 0.8651808 | AM11: =AD$1*((-0.000002)*AD11^3+0.00032*AD11^2+(-0.0021)*AD11)+AE$1*((-0.000002)*AE11^3+0.00032*AE11^2+(-0.0021)*AE11)+AF$1*((-0.000002)*AF11^3+0.00032*AF11^2+(-0.0021)*AF11)+AG$1*((-0.000002)*AG11^3+0.00032*AG11^2+(-0.0021)*AG11) -> 0.7734448
A12: =IFERROR((AI12*AI$3+AJ12*AJ$3+AK12*AK$3+AL12*AL$3+AM12*AM$3)*100/(AI$5*AI$3+AJ$5*AJ$3+AK$5*AK$3+AL$5*AL$3+AM$5*AM$3),0) -> 63.931151 | B12: 11 | C12: Sanchez, Angel | D12: LF | E12: S | F12: L | G12: 18 | H12: 77 | I12: 77 | J12: 61 | K12: 71 | L12: 62 | M12: 21 | N12: 0 | O12: 26 | P12: 73 | Q12: 11 | R12: Sanchez, Angel | S12: LF | T12: S | U12: L | V12: 18 | W12: 53 | X12: 47 | Y12: 46 | Z12: 56 | AA12: 14 | AB12: 91 | AC12: 100 | AD12: 43 | AE12: 81 | AF12: 23 | AG12: 44 | AH12: 73 | AI12: =H$1*((-0.000002)*H12^3+0.00032*H12^2+(-0.0021)*H12)+I$1*((-0.000002)*I12^3+0.00032*I12^2+(-0.0021)*I12)+J$1*((-0.000002)*J12^3+0.00032*J12^2+(-0.0021)*J12)+K$1*((-0.000002)*K12^3+0.00032*K12^2+(-0.0021)*K12)+L$1*((-0.000002)*L12^3+0.00032*L12^2+(-0.0021)*L12) -> 5.1356988 | AJ12: =M$1*((-0.000002)*M12^3+0.00032*M12^2+(-0.0021)*M12)+N$1*((-0.000002)*N12^3+0.00032*N12^2+(-0.0021)*N12)+O$1*((-0.000002)*O12^3+0.00032*O12^2+(-0.0021)*O12) -> 0.0911548 | AK12: =IF(AA12<50,W$1*((-0.000002)*W12^3+0.00032*W12^2+(-0.0021)*W12)+X$1*((-0.000002)*X12^3+0.00032*X12^2+(-0.0021)*X12)+Y$1*((-0.000002)*Y12^3+0.00032*Y12^2+(-0.0021)*Y12)+Z$1*((-0.000002)*Z12^3+0.00032*Z12^2+(-0.0021)*Z12),X$2*((-0.000002)*X12^3+0.00032*X12^2+(-0.0021)*X12)+Y$2*((-0.000002)*Y12^3+0.00032*Y12^2+(-0.0021)*Y12)+Z$2*((-0.000002)*Z12^3+0.00032*Z12^2+(-0.0021)*Z12)+AA$2*((-0.000002)*AA12^3+0.00032*AA12^2+(-0.0021)*AA12)) -> 1.810896 | AL12: =AB$1*((-0.000002)*AB12^3+0.00032*AB12^2+(-0.0021)*AB12)+AC$1*((-0.000002)*AC12^3+0.00032*AC12^2+(-0.0021)*AC12) -> 0.9593424 | AM12: =AD$1*((-0.000002)*AD12^3+0.00032*AD12^2+(-0.0021)*AD12)+AE$1*((-0.000002)*AE12^3+0.00032*AE12^2+(-0.0021)*AE12)+AF$1*((-0.000002)*AF12^3+0.00032*AF12^2+(-0.0021)*AF12)+AG$1*((-0.000002)*AG12^3+0.00032*AG12^2+(-0.0021)*AG12) -> 0.4743596
A13: =IFERROR((AI13*AI$3+AJ13*AJ$3+AK13*AK$3+AL13*AL$3+AM13*AM$3)*100/(AI$5*AI$3+AJ$5*AJ$3+AK$5*AK$3+AL$5*AL$3+AM$5*AM$3),0) -> 62.680297 | B13: 12 | C13: Arguelles, Arquimedes | D13: 2B | E13: R | F13: R | G13: 18 | H13: 93 | I13: 28 | J13: 44 | K13: 59 | L13: 59 | M13: 74 | N13: 77 | O13: 45 | P13: 80 | Q13: 12 | R13: Arguelles, Arquimedes | S13: 2B | T13: R | U13: R | V13: 18 | W13: 100 | X13: 83 | Y13: 60 | Z13: 80 | AA13: 21 | AB13: 85 | AC13: 100 | AD13: 95 | AE13: 82 | AF13: 0 | AG13: 52 | AH13: 80 | AI13: =H$1*((-0.000002)*H13^3+0.00032*H13^2+(-0.0021)*H13)+I$1*((-0.000002)*I13^3+0.00032*I13^2+(-0.0021)*I13)+J$1*((-0.000002)*J13^3+0.00032*J13^2+(-0.0021)*J13)+K$1*((-0.000002)*K13^3+0.00032*K13^2+(-0.0021)*K13)+L$1*((-0.000002)*L13^3+0.00032*L13^2+(-0.0021)*L13) -> 3.4314368 | AJ13: =M$1*((-0.000002)*M13^3+0.00032*M13^2+(-0.0021)*M13)+N$1*((-0.000002)*N13^3+0.00032*N13^2+(-0.0021)*N13)+O$1*((-0.000002)*O13^3+0.00032*O13^2+(-0.0021)*O13) -> 0.9880998 | AK13: =IF(AA13<50,W$1*((-0.000002)*W13^3+0.00032*W13^2+(-0.0021)*W13)+X$1*((-0.000002)*X13^3+0.00032*X13^2+(-0.0021)*X13)+Y$1*((-0.000002)*Y13^3+0.00032*Y13^2+(-0.0021)*Y13)+Z$1*((-0.000002)*Z13^3+0.00032*Z13^2+(-0.0021)*Z13),X$2*((-0.000002)*X13^3+0.00032*X13^2+(-0.0021)*X13)+Y$2*((-0.000002)*Y13^3+0.00032*Y13^2+(-0.0021)*Y13)+Z$2*((-0.000002)*Z13^3+0.00032*Z13^2+(-0.0021)*Z13)+AA$2*((-0.000002)*AA13^3+0.00032*AA13^2+(-0.0021)*AA13)) -> 3.326606 | AL13: =AB$1*((-0.000002)*AB13^3+0.00032*AB13^2+(-0.0021)*AB13)+AC$1*((-0.000002)*AC13^3+0.00032*AC13^2+(-0.0021)*AC13) -> 0.9222 | AM13: =AD$1*((-0.000002)*AD13^3+0.00032*AD13^2+(-0.0021)*AD13)+AE$1*((-0.000002)*AE13^3+0.00032*AE13^2+(-0.0021)*AE13)+AF$1*((-0.000002)*AF13^3+0.00032*AF13^2+(-0.0021)*AF13)+AG$1*((-0.000002)*AG13^3+0.00032*AG13^2+(-0.0021)*AG13) -> 1.1089108
A14: =IFERROR((AI14*AI$3+AJ14*AJ$3+AK14*AK$3+AL14*AL$3+AM14*AM$3)*100/(AI$5*AI$3+AJ$5*AJ$3+AK$5*AK$3+AL$5*AL$3+AM$5*AM$3),0) -> 68.597196 | B14: 14 | C14: Finnegan, Johermyn | D14: SS | E14: L | F14: R | G14: 18 | H14: 73 | I14: 51 | J14: 33 | K14: 67 | L14: 60 | M14: 72 | N14: 42 | O14: 47 | P14: 73 | Q14: 14 | R14: Finnegan, Johermyn | S14: SS | T14: L | U14: R | V14: 18 | W14: 89 | X14: 100 | Y14: 100 | Z14: 86 | AA14: 2 | AB14: 74 | AC14: 85 | AD14: 57 | AE14: 66 | AF14: 87 | AG14: 62 | AH14: 73 | AI14: =H$1*((-0.000002)*H14^3+0.00032*H14^2+(-0.0021)*H14)+I$1*((-0.000002)*I14^3+0.00032*I14^2+(-0.0021)*I14)+J$1*((-0.000002)*J14^3+0.00032*J14^2+(-0.0021)*J14)+K$1*((-0.000002)*K14^3+0.00032*K14^2+(-0.0021)*K14)+L$1*((-0.000002)*L14^3+0.00032*L14^2+(-0.0021)*L14) -> 3.839382 | AJ14: =M$1*((-0.000002)*M14^3+0.00032*M14^2+(-0.0021)*M14)+N$1*((-0.000002)*N14^3+0.00032*N14^2+(-0.0021)*N14)+O$1*((-0.000002)*O14^3+0.00032*O14^2+(-0.0021)*O14) -> 0.8668582 | AK14: =IF(AA14<50,W$1*((-0.000002)*W14^3+0.00032*W14^2+(-0.0021)*W14)+X$1*((-0.000002)*X14^3+0.00032*X14^2+(-0.0021)*X14)+Y$1*((-0.000002)*Y14^3+0.00032*Y14^2+(-0.0021)*Y14)+Z$1*((-0.000002)*Z14^3+0.00032*Z14^2+(-0.0021)*Z14),X$2*((-0.000002)*X14^3+0.00032*X14^2+(-0.0021)*X14)+Y$2*((-0.000002)*Y14^3+0.00032*Y14^2+(-0.0021)*Y14)+Z$2*((-0.000002)*Z14^3+0.00032*Z14^2+(-0.0021)*Z14)+AA$2*((-0.000002)*AA14^3+0.00032*AA14^2+(-0.0021)*AA14)) -> 3.83189 | AL14: =AB$1*((-0.000002)*AB14^3+0.00032*AB14^2+(-0.0021)*AB14)+AC$1*((-0.000002)*AC14^3+0.00032*AC14^2+(-0.0021)*AC14) -> 0.8102276 | AM14: =AD$1*((-0.000002)*AD14^3+0.00032*AD14^2+(-0.0021)*AD14)+AE$1*((-0.000002)*AE14^3+0.00032*AE14^2+(-0.0021)*AE14)+AF$1*((-0.000002)*AF14^3+0.00032*AF14^2+(-0.0021)*AF14)+AG$1*((-0.000002)*AG14^3+0.00032*AG14^2+(-0.0021)*AG14) -> 0.7721866
A15: =IFERROR((AI15*AI$3+AJ15*AJ$3+AK15*AK$3+AL15*AL$3+AM15*AM$3)*100/(AI$5*AI$3+AJ$5*AJ$3+AK$5*AK$3+AL$5*AL$3+AM$5*AM$3),0) -> 60.439092 | B15: 17 | C15: Nieves, Julio | D15: LF | E15: L | F15: L | G15: 18 | H15: 89 | I15: 56 | J15: 56 | K15: 58 | L15: 57 | M15: 95 | N15: 32 | O15: 31 | P15: 74 | Q15: 17 | R15: Nieves, Julio | S15: LF | T15: L | U15: L | V15: 18 | W15: 61 | X15: 50 | Y15: 48 | Z15: 58 | AA15: 11 | AB15: 84 | AC15: 89 | AD15: 63 | AE15: 56 | AF15: 62 | AG15: 56 | AH15: 74 | AI15: =H$1*((-0.000002)*H15^3+0.00032*H15^2+(-0.0021)*H15)+I$1*((-0.000002)*I15^3+0.00032*I15^2+(-0.0021)*I15)+J$1*((-0.000002)*J15^3+0.00032*J15^2+(-0.0021)*J15)+K$1*((-0.000002)*K15^3+0.00032*K15^2+(-0.0021)*K15)+L$1*((-0.000002)*L15^3+0.00032*L15^2+(-0.0021)*L15) -> 4.28622 | AJ15: =M$1*((-0.000002)*M15^3+0.00032*M15^2+(-0.0021)*M15)+N$1*((-0.000002)*N15^3+0.00032*N15^2+(-0.0021)*N15)+O$1*((-0.000002)*O15^3+0.00032*O15^2+(-0.0021)*O15) -> 1.0310226 | AK15: =IF(AA15<50,W$1*((-0.000002)*W15^3+0.00032*W15^2+(-0.0021)*W15)+X$1*((-0.000002)*X15^3+0.00032*X15^2+(-0.0021)*X15)+Y$1*((-0.000002)*Y15^3+0.00032*Y15^2+(-0.0021)*Y15)+Z$1*((-0.000002)*Z15^3+0.00032*Z15^2+(-0.0021)*Z15),X$2*((-0.000002)*X15^3+0.00032*X15^2+(-0.0021)*X15)+Y$2*((-0.000002)*Y15^3+0.00032*Y15^2+(-0.0021)*Y15)+Z$2*((-0.000002)*Z15^3+0.00032*Z15^2+(-0.0021)*Z15)+AA$2*((-0.000002)*AA15^3+0.00032*AA15^2+(-0.0021)*AA15)) -> 2.03341 | AL15: =AB$1*((-0.000002)*AB15^3+0.00032*AB15^2+(-0.0021)*AB15)+AC$1*((-0.000002)*AC15^3+0.00032*AC15^2+(-0.0021)*AC15) -> 0.904466 | AM15: =AD$1*((-0.000002)*AD15^3+0.00032*AD15^2+(-0.0021)*AD15)+AE$1*((-0.000002)*AE15^3+0.00032*AE15^2+(-0.0021)*AE15)+AF$1*((-0.000002)*AF15^3+0.00032*AF15^2+(-0.0021)*AF15)+AG$1*((-0.000002)*AG15^3+0.00032*AG15^2+(-0.0021)*AG15) -> 0.806946
A16: =IFERROR((AI16*AI$3+AJ16*AJ$3+AK16*AK$3+AL16*AL$3+AM16*AM$3)*100/(AI$5*AI$3+AJ$5*AJ$3+AK$5*AK$3+AL$5*AL$3+AM$5*AM$3),0) -> 66.857347 | B16: 18 | C16: Cruz, Yamid | D16: 2B | E16: R | F16: R | G16: 18 | H16: 26 | I16: 100 | J16: 60 | K16: 66 | L16: 76 | M16: 42 | N16: 31 | O16: 44 | P16: 61 | Q16: 18 | R16: Cruz, Yamid | S16: 2B | T16: R | U16: R | V16: 18 | W16: 64 | X16: 64 | Y16: 66 | Z16: 70 | AA16: 18 | AB16: 56 | AC16: 97 | AD16: 26 | AE16: 65 | AF16: 66 | AG16: 35 | AH16: 61 | AI16: =H$1*((-0.000002)*H16^3+0.00032*H16^2+(-0.0021)*H16)+I$1*((-0.000002)*I16^3+0.00032*I16^2+(-0.0021)*I16)+J$1*((-0.000002)*J16^3+0.00032*J16^2+(-0.0021)*J16)+K$1*((-0.000002)*K16^3+0.00032*K16^2+(-0.0021)*K16)+L$1*((-0.000002)*L16^3+0.00032*L16^2+(-0.0021)*L16) -> 4.839504 | AJ16: =M$1*((-0.000002)*M16^3+0.00032*M16^2+(-0.0021)*M16)+N$1*((-0.000002)*N16^3+0.00032*N16^2+(-0.0021)*N16)+O$1*((-0.000002)*O16^3+0.00032*O16^2+(-0.0021)*O16) -> 0.4003468 | AK16: =IF(AA16<50,W$1*((-0.000002)*W16^3+0.00032*W16^2+(-0.0021)*W16)+X$1*((-0.000002)*X16^3+0.00032*X16^2+(-0.0021)*X16)+Y$1*((-0.000002)*Y16^3+0.00032*Y16^2+(-0.0021)*Y16)+Z$1*((-0.000002)*Z16^3+0.00032*Z16^2+(-0.0021)*Z16),X$2*((-0.000002)*X16^3+0.00032*X16^2+(-0.0021)*X16)+Y$2*((-0.000002)*Y16^3+0.00032*Y16^2+(-0.0021)*Y16)+Z$2*((-0.000002)*Z16^3+0.00032*Z16^2+(-0.0021)*Z16)+AA$2*((-0.000002)*AA16^3+0.00032*AA16^2+(-0.0021)*AA16)) -> 2.719392 | AL16: =AB$1*((-0.000002)*AB16^3+0.00032*AB16^2+(-0.0021)*AB16)+AC$1*((-0.000002)*AC16^3+0.00032*AC16^2+(-0.0021)*AC16) -> 0.6241172 | AM16: =AD$1*((-0.000002)*AD16^3+0.00032*AD16^2+(-0.0021)*AD16)+AE$1*((-0.000002)*AE16^3+0.00032*AE16^2+(-0.0021)*AE16)+AF$1*((-0.000002)*AF16^3+0.00032*AF16^2+(-0.0021)*AF16)+AG$1*((-0.000002)*AG16^3+0.00032*AG16^2+(-0.0021)*AG16) -> 0.2845008
A17: =IFERROR((AI17*AI$3+AJ17*AJ$3+AK17*AK$3+AL17*AL$3+AM17*AM$3)*100/(AI$5*AI$3+AJ$5*AJ$3+AK$5*AK$3+AL$5*AL$3+AM$5*AM$3),0) -> 73.006889 | B17: 19 | C17: Duchscherer, Bobby Joe | D17: 2B | E17: R | F17: R | G17: 18 | H17: 85 | I17: 73 | J17: 75 | K17: 62 | L17: 64 | M17: 79 | N17: 76 | O17: 48 | P17: 85 | Q17: 19 | R17: Duchscherer, Bobby Joe | S17: 2B | T17: R | U17: R | V17: 18 | W17: 83 | X17: 60 | Y17: 51 | Z17: 59 | AA17: 30 | AB17: 84 | AC17: 82 | AD17: 87 | AE17: 62 | AF17: 32 | AG17: 91 | AH17: 85 | AI17: =H$1*((-0.000002)*H17^3+0.00032*H17^2+(-0.0021)*H17)+I$1*((-0.000002)*I17^3+0.00032*I17^2+(-0.0021)*I17)+J$1*((-0.000002)*J17^3+0.00032*J17^2+(-0.0021)*J17)+K$1*((-0.000002)*K17^3+0.00032*K17^2+(-0.0021)*K17)+L$1*((-0.000002)*L17^3+0.00032*L17^2+(-0.0021)*L17) -> 5.224062 | AJ17: =M$1*((-0.000002)*M17^3+0.00032*M17^2+(-0.0021)*M17)+N$1*((-0.000002)*N17^3+0.00032*N17^2+(-0.0021)*N17)+O$1*((-0.000002)*O17^3+0.00032*O17^2+(-0.0021)*O17) -> 1.0488252 | AK17: =IF(AA17<50,W$1*((-0.000002)*W17^3+0.00032*W17^2+(-0.0021)*W17)+X$1*((-0.000002)*X17^3+0.00032*X17^2+(-0.0021)*X17)+Y$1*((-0.000002)*Y17^3+0.00032*Y17^2+(-0.0021)*Y17)+Z$1*((-0.000002)*Z17^3+0.00032*Z17^2+(-0.0021)*Z17),X$2*((-0.000002)*X17^3+0.00032*X17^2+(-0.0021)*X17)+Y$2*((-0.000002)*Y17^3+0.00032*Y17^2+(-0.0021)*Y17)+Z$2*((-0.000002)*Z17^3+0.00032*Z17^2+(-0.0021)*Z17)+AA$2*((-0.000002)*AA17^3+0.00032*AA17^2+(-0.0021)*AA17)) -> 2.519786 | AL17: =AB$1*((-0.000002)*AB17^3+0.00032*AB17^2+(-0.0021)*AB17)+AC$1*((-0.000002)*AC17^3+0.00032*AC17^2+(-0.0021)*AC17) -> 0.8922384 | AM17: =AD$1*((-0.000002)*AD17^3+0.00032*AD17^2+(-0.0021)*AD17)+AE$1*((-0.000002)*AE17^3+0.00032*AE17^2+(-0.0021)*AE17)+AF$1*((-0.000002)*AF17^3+0.00032*AF17^2+(-0.0021)*AF17)+AG$1*((-0.000002)*AG17^3+0.00032*AG17^2+(-0.0021)*AG17) -> 1.0993586
A18: =IFERROR((AI18*AI$3+AJ18*AJ$3+AK18*AK$3+AL18*AL$3+AM18*AM$3)*100/(AI$5*AI$3+AJ$5*AJ$3+AK$5*AK$3+AL$5*AL$3+AM$5*AM$3),0) -> 55.804694 | B18: 22 | C18: Morris, Dillon | D18: SS | E18: S | F18: R | G18: 18 | H18: 55 | I18: 58 | J18: 22 | K18: 41 | L18: 38 | M18: 70 | N18: 23 | O18: 31 | P18: 67 | Q18: 22 | R18: Morris, Dillon | S18: SS | T18: S | U18: R | V18: 18 | W18: 83 | X18: 76 | Y18: 80 | Z18: 86 | AA18: 5 | AB18: 87 | AC18: 78 | AD18: 67 | AE18: 84 | AF18: 85 | AG18: 68 | AH18: 67 | AI18: =H$1*((-0.000002)*H18^3+0.00032*H18^2+(-0.0021)*H18)+I$1*((-0.000002)*I18^3+0.00032*I18^2+(-0.0021)*I18)+J$1*((-0.000002)*J18^3+0.00032*J18^2+(-0.0021)*J18)+K$1*((-0.000002)*K18^3+0.00032*K18^2+(-0.0021)*K18)+L$1*((-0.000002)*L18^3+0.00032*L18^2+(-0.0021)*L18) -> 2.6528272 | AJ18: =M$1*((-0.000002)*M18^3+0.00032*M18^2+(-0.0021)*M18)+N$1*((-0.000002)*N18^3+0.00032*N18^2+(-0.0021)*N18)+O$1*((-0.000002)*O18^3+0.00032*O18^2+(-0.0021)*O18) -> 0.772613 | AK18: =IF(AA18<50,W$1*((-0.000002)*W18^3+0.00032*W18^2+(-0.0021)*W18)+X$1*((-0.000002)*X18^3+0.00032*X18^2+(-0.0021)*X18)+Y$1*((-0.000002)*Y18^3+0.00032*Y18^2+(-0.0021)*Y18)+Z$1*((-0.000002)*Z18^3+0.00032*Z18^2+(-0.0021)*Z18),X$2*((-0.000002)*X18^3+0.00032*X18^2+(-0.0021)*X18)+Y$2*((-0.000002)*Y18^3+0.00032*Y18^2+(-0.0021)*Y18)+Z$2*((-0.000002)*Z18^3+0.00032*Z18^2+(-0.0021)*Z18)+AA$2*((-0.000002)*AA18^3+0.00032*AA18^2+(-0.0021)*AA18)) -> 3.467382 | AL18: =AB$1*((-0.000002)*AB18^3+0.00032*AB18^2+(-0.0021)*AB18)+AC$1*((-0.000002)*AC18^3+0.00032*AC18^2+(-0.0021)*AC18) -> 0.9046944 | AM18: =AD$1*((-0.000002)*AD18^3+0.00032*AD18^2+(-0.0021)*AD18)+AE$1*((-0.000002)*AE18^3+0.00032*AE18^2+(-0.0021)*AE18)+AF$1*((-0.000002)*AF18^3+0.00032*AF18^2+(-0.0021)*AF18)+AG$1*((-0.000002)*AG18^3+0.00032*AG18^2+(-0.0021)*AG18) -> 0.9451918
... A85: =IFERROR((AI85*AI$3+AJ85*AJ$3+AK85*AK$3+AL85*AL$3+AM85*AM$3)*100/(AI$5*AI$3+AJ$5*AJ$3+AK$5*AK$3+AL$5*AL$3+AM$5*AM$3),0) -> 29.107011 | B85: 141 | C85: Harper, Moe | D85: DH | E85: R | F85: R | G85: 21 | H85: 34 | I85: 12 | J85: 46 | K85: 28 | L85: 61 | M85: 21 | N85: 0 | O85: 20 | P85: 42 | Q85: 141 | R85: Harper, Moe | S85: DH | T85: R | U85: R | V85: 21 | W85: 0 | X85: 45 | Y85: 45 | Z85: 51 | AA85: 0 | AB85: 94 | AC85: 62 | AD85: 19 | AE85: 86 | AF85: 33 | AG85: 59 | AH85: 42 | AI85: =H$1*((-0.000002)*H85^3+0.00032*H85^2+(-0.0021)*H85)+I$1*((-0.000002)*I85^3+0.00032*I85^2+(-0.0021)*I85)+J$1*((-0.000002)*J85^3+0.00032*J85^2+(-0.0021)*J85)+K$1*((-0.000002)*K85^3+0.00032*K85^2+(-0.0021)*K85)+L$1*((-0.000002)*L85^3+0.00032*L85^2+(-0.0021)*L85) -> 1.8362544 | AJ85: =M$1*((-0.000002)*M85^3+0.00032*M85^2+(-0.0021)*M85)+N$1*((-0.000002)*N85^3+0.00032*N85^2+(-0.0021)*N85)+O$1*((-0.000002)*O85^3+0.00032*O85^2+(-0.0021)*O85) -> 0.085498 | AK85: =IF(AA85<50,W$1*((-0.000002)*W85^3+0.00032*W85^2+(-0.0021)*W85)+X$1*((-0.000002)*X85^3+0.00032*X85^2+(-0.0021)*X85)+Y$1*((-0.000002)*Y85^3+0.00032*Y85^2+(-0.0021)*Y85)+Z$1*((-0.000002)*Z85^3+0.00032*Z85^2+(-0.0021)*Z85),X$2*((-0.000002)*X85^3+0.00032*X85^2+(-0.0021)*X85)+Y$2*((-0.000002)*Y85^3+0.00032*Y85^2+(-0.0021)*Y85)+Z$2*((-0.000002)*Z85^3+0.00032*Z85^2+(-0.0021)*Z85)+AA$2*((-0.000002)*AA85^3+0.00032*AA85^2+(-0.0021)*AA85)) -> 1.202418 | AL85: =AB$1*((-0.000002)*AB85^3+0.00032*AB85^2+(-0.0021)*AB85)+AC$1*((-0.000002)*AC85^3+0.00032*AC85^2+(-0.0021)*AC85) -> 0.8998064 | AM85: =AD$1*((-0.000002)*AD85^3+0.00032*AD85^2+(-0.0021)*AD85)+AE$1*((-0.000002)*AE85^3+0.00032*AE85^2+(-0.0021)*AE85)+AF$1*((-0.000002)*AF85^3+0.00032*AF85^2+(-0.0021)*AF85)+AG$1*((-0.000002)*AG85^3+0.00032*AG85^2+(-0.0021)*AG85) -> 0.2319596
A86: =IFERROR((AI86*AI$3+AJ86*AJ$3+AK86*AK$3+AL86*AL$3+AM86*AM$3)*100/(AI$5*AI$3+AJ$5*AJ$3+AK$5*AK$3+AL$5*AL$3+AM$5*AM$3),0) -> 0 | B86: 227 | C86: Hodges, John | D86: C | E86: L | F86: R | G86: 21 | H86: ? | I86: ? | J86: ? | K86: ? | L86: ? | M86: ? | N86: ? | O86: ? | P86: ? | Q86: 227 | R86: Hodges, John | S86: C | T86: L | U86: R | V86: 21 | W86: ? | X86: ? | Y86: ? | Z86: ? | AA86: ? | AB86: ? | AC86: ? | AD86: ? | AE86: ? | AF86: ? | AG86: ? | AH86: ? | AI86: =H$1*((-0.000002)*H86^3+0.00032*H86^2+(-0.0021)*H86)+I$1*((-0.000002)*I86^3+0.00032*I86^2+(-0.0021)*I86)+J$1*((-0.000002)*J86^3+0.00032*J86^2+(-0.0021)*J86)+K$1*((-0.000002)*K86^3+0.00032*K86^2+(-0.0021)*K86)+L$1*((-0.000002)*L86^3+0.00032*L86^2+(-0.0021)*L86) -> #VALUE! | AJ86: =M$1*((-0.000002)*M86^3+0.00032*M86^2+(-0.0021)*M86)+N$1*((-0.000002)*N86^3+0.00032*N86^2+(-0.0021)*N86)+O$1*((-0.000002)*O86^3+0.00032*O86^2+(-0.0021)*O86) -> #VALUE! | AK86: =IF(AA86<50,W$1*((-0.000002)*W86^3+0.00032*W86^2+(-0.0021)*W86)+X$1*((-0.000002)*X86^3+0.00032*X86^2+(-0.0021)*X86)+Y$1*((-0.000002)*Y86^3+0.00032*Y86^2+(-0.0021)*Y86)+Z$1*((-0.000002)*Z86^3+0.00032*Z86^2+(-0.0021)*Z86),X$2*((-0.000002)*X86^3+0.00032*X86^2+(-0.0021)*X86)+Y$2*((-0.000002)*Y86^3+0.00032*Y86^2+(-0.0021)*Y86)+Z$2*((-0.000002)*Z86^3+0.00032*Z86^2+(-0.0021)*Z86)+AA$2*((-0.000002)*AA86^3+0.00032*AA86^2+(-0.0021)*AA86)) -> #VALUE! | AL86: =AB$1*((-0.000002)*AB86^3+0.00032*AB86^2+(-0.0021)*AB86)+AC$1*((-0.000002)*AC86^3+0.00032*AC86^2+(-0.0021)*AC86) -> #VALUE! | AM86: =AD$1*((-0.000002)*AD86^3+0.00032*AD86^2+(-0.0021)*AD86)+AE$1*((-0.000002)*AE86^3+0.00032*AE86^2+(-0.0021)*AE86)+AF$1*((-0.000002)*AF86^3+0.00032*AF86^2+(-0.0021)*AF86)+AG$1*((-0.000002)*AG86^3+0.00032*AG86^2+(-0.0021)*AG86) -> #VALUE!
A87: =IFERROR((AI87*AI$3+AJ87*AJ$3+AK87*AK$3+AL87*AL$3+AM87*AM$3)*100/(AI$5*AI$3+AJ$5*AJ$3+AK$5*AK$3+AL$5*AL$3+AM$5*AM$3),0) -> 0 | B87: 228 | C87: Ramirez, Gerardo | D87: C | E87: R | F87: R | G87: 21 | H87: ? | I87: ? | J87: ? | K87: ? | L87: ? | M87: ? | N87: ? | O87: ? | P87: ? | Q87: 228 | R87: Ramirez, Gerardo | S87: C | T87: R | U87: R | V87: 21 | W87: ? | X87: ? | Y87: ? | Z87: ? | AA87: ? | AB87: ? | AC87: ? | AD87: ? | AE87: ? | AF87: ? | AG87: ? | AH87: ? | AI87: =H$1*((-0.000002)*H87^3+0.00032*H87^2+(-0.0021)*H87)+I$1*((-0.000002)*I87^3+0.00032*I87^2+(-0.0021)*I87)+J$1*((-0.000002)*J87^3+0.00032*J87^2+(-0.0021)*J87)+K$1*((-0.000002)*K87^3+0.00032*K87^2+(-0.0021)*K87)+L$1*((-0.000002)*L87^3+0.00032*L87^2+(-0.0021)*L87) -> #VALUE! | AJ87: =M$1*((-0.000002)*M87^3+0.00032*M87^2+(-0.0021)*M87)+N$1*((-0.000002)*N87^3+0.00032*N87^2+(-0.0021)*N87)+O$1*((-0.000002)*O87^3+0.00032*O87^2+(-0.0021)*O87) -> #VALUE! | AK87: =IF(AA87<50,W$1*((-0.000002)*W87^3+0.00032*W87^2+(-0.0021)*W87)+X$1*((-0.000002)*X87^3+0.00032*X87^2+(-0.0021)*X87)+Y$1*((-0.000002)*Y87^3+0.00032*Y87^2+(-0.0021)*Y87)+Z$1*((-0.000002)*Z87^3+0.00032*Z87^2+(-0.0021)*Z87),X$2*((-0.000002)*X87^3+0.00032*X87^2+(-0.0021)*X87)+Y$2*((-0.000002)*Y87^3+0.00032*Y87^2+(-0.0021)*Y87)+Z$2*((-0.000002)*Z87^3+0.00032*Z87^2+(-0.0021)*Z87)+AA$2*((-0.000002)*AA87^3+0.00032*AA87^2+(-0.0021)*AA87)) -> #VALUE! | AL87: =AB$1*((-0.000002)*AB87^3+0.00032*AB87^2+(-0.0021)*AB87)+AC$1*((-0.000002)*AC87^3+0.00032*AC87^2+(-0.0021)*AC87) -> #VALUE! | AM87: =AD$1*((-0.000002)*AD87^3+0.00032*AD87^2+(-0.0021)*AD87)+AE$1*((-0.000002)*AE87^3+0.00032*AE87^2+(-0.0021)*AE87)+AF$1*((-0.000002)*AF87^3+0.00032*AF87^2+(-0.0021)*AF87)+AG$1*((-0.000002)*AG87^3+0.00032*AG87^2+(-0.0021)*AG87) -> #VALUE!
A88: =IFERROR((AI88*AI$3+AJ88*AJ$3+AK88*AK$3+AL88*AL$3+AM88*AM$3)*100/(AI$5*AI$3+AJ$5*AJ$3+AK$5*AK$3+AL$5*AL$3+AM$5*AM$3),0) -> 0 | B88: 229 | C88: Davis, Alan | D88: C | E88: R | F88: R | G88: 21 | H88: ? | I88: ? | J88: ? | K88: ? | L88: ? | M88: ? | N88: ? | O88: ? | P88: ? | Q88: 229 | R88: Davis, Alan | S88: C | T88: R | U88: R | V88: 21 | W88: ? | X88: ? | Y88: ? | Z88: ? | AA88: ? | AB88: ? | AC88: ? | AD88: ? | AE88: ? | AF88: ? | AG88: ? | AH88: ? | AI88: =H$1*((-0.000002)*H88^3+0.00032*H88^2+(-0.0021)*H88)+I$1*((-0.000002)*I88^3+0.00032*I88^2+(-0.0021)*I88)+J$1*((-0.000002)*J88^3+0.00032*J88^2+(-0.0021)*J88)+K$1*((-0.000002)*K88^3+0.00032*K88^2+(-0.0021)*K88)+L$1*((-0.000002)*L88^3+0.00032*L88^2+(-0.0021)*L88) -> #VALUE! | AJ88: =M$1*((-0.000002)*M88^3+0.00032*M88^2+(-0.0021)*M88)+N$1*((-0.000002)*N88^3+0.00032*N88^2+(-0.0021)*N88)+O$1*((-0.000002)*O88^3+0.00032*O88^2+(-0.0021)*O88) -> #VALUE! | AK88: =IF(AA88<50,W$1*((-0.000002)*W88^3+0.00032*W88^2+(-0.0021)*W88)+X$1*((-0.000002)*X88^3+0.00032*X88^2+(-0.0021)*X88)+Y$1*((-0.000002)*Y88^3+0.00032*Y88^2+(-0.0021)*Y88)+Z$1*((-0.000002)*Z88^3+0.00032*Z88^2+(-0.0021)*Z88),X$2*((-0.000002)*X88^3+0.00032*X88^2+(-0.0021)*X88)+Y$2*((-0.000002)*Y88^3+0.00032*Y88^2+(-0.0021)*Y88)+Z$2*((-0.000002)*Z88^3+0.00032*Z88^2+(-0.0021)*Z88)+AA$2*((-0.000002)*AA88^3+0.00032*AA88^2+(-0.0021)*AA88)) -> #VALUE! | AL88: =AB$1*((-0.000002)*AB88^3+0.00032*AB88^2+(-0.0021)*AB88)+AC$1*((-0.000002)*AC88^3+0.00032*AC88^2+(-0.0021)*AC88) -> #VALUE! | AM88: =AD$1*((-0.000002)*AD88^3+0.00032*AD88^2+(-0.0021)*AD88)+AE$1*((-0.000002)*AE88^3+0.00032*AE88^2+(-0.0021)*AE88)+AF$1*((-0.000002)*AF88^3+0.00032*AF88^2+(-0.0021)*AF88)+AG$1*((-0.000002)*AG88^3+0.00032*AG88^2+(-0.0021)*AG88) -> #VALUE!
A89: =IFERROR((AI89*AI$3+AJ89*AJ$3+AK89*AK$3+AL89*AL$3+AM89*AM$3)*100/(AI$5*AI$3+AJ$5*AJ$3+AK$5*AK$3+AL$5*AL$3+AM$5*AM$3),0) -> 0 | B89: 230 | C89: Miley, Johan | D89: C | E89: R | F89: R | G89: 22 | H89: ? | I89: ? | J89: ? | K89: ? | L89: ? | M89: ? | N89: ? | O89: ? | P89: ? | Q89: 230 | R89: Miley, Johan | S89: C | T89: R | U89: R | V89: 22 | W89: ? | X89: ? | Y89: ? | Z89: ? | AA89: ? | AB89: ? | AC89: ? | AD89: ? | AE89: ? | AF89: ? | AG89: ? | AH89: ? | AI89: =H$1*((-0.000002)*H89^3+0.00032*H89^2+(-0.0021)*H89)+I$1*((-0.000002)*I89^3+0.00032*I89^2+(-0.0021)*I89)+J$1*((-0.000002)*J89^3+0.00032*J89^2+(-0.0021)*J89)+K$1*((-0.000002)*K89^3+0.00032*K89^2+(-0.0021)*K89)+L$1*((-0.000002)*L89^3+0.00032*L89^2+(-0.0021)*L89) -> #VALUE! | AJ89: =M$1*((-0.000002)*M89^3+0.00032*M89^2+(-0.0021)*M89)+N$1*((-0.000002)*N89^3+0.00032*N89^2+(-0.0021)*N89)+O$1*((-0.000002)*O89^3+0.00032*O89^2+(-0.0021)*O89) -> #VALUE! | AK89: =IF(AA89<50,W$1*((-0.000002)*W89^3+0.00032*W89^2+(-0.0021)*W89)+X$1*((-0.000002)*X89^3+0.00032*X89^2+(-0.0021)*X89)+Y$1*((-0.000002)*Y89^3+0.00032*Y89^2+(-0.0021)*Y89)+Z$1*((-0.000002)*Z89^3+0.00032*Z89^2+(-0.0021)*Z89),X$2*((-0.000002)*X89^3+0.00032*X89^2+(-0.0021)*X89)+Y$2*((-0.000002)*Y89^3+0.00032*Y89^2+(-0.0021)*Y89)+Z$2*((-0.000002)*Z89^3+0.00032*Z89^2+(-0.0021)*Z89)+AA$2*((-0.000002)*AA89^3+0.00032*AA89^2+(-0.0021)*AA89)) -> #VALUE! | AL89: =AB$1*((-0.000002)*AB89^3+0.00032*AB89^2+(-0.0021)*AB89)+AC$1*((-0.000002)*AC89^3+0.00032*AC89^2+(-0.0021)*AC89) -> #VALUE! | AM89: =AD$1*((-0.000002)*AD89^3+0.00032*AD89^2+(-0.0021)*AD89)+AE$1*((-0.000002)*AE89^3+0.00032*AE89^2+(-0.0021)*AE89)+AF$1*((-0.000002)*AF89^3+0.00032*AF89^2+(-0.0021)*AF89)+AG$1*((-0.000002)*AG89^3+0.00032*AG89^2+(-0.0021)*AG89) -> #VALUE!
A90: =IFERROR((AI90*AI$3+AJ90*AJ$3+AK90*AK$3+AL90*AL$3+AM90*AM$3)*100/(AI$5*AI$3+AJ$5*AJ$3+AK$5*AK$3+AL$5*AL$3+AM$5*AM$3),0) -> 0 | B90: 231 | C90: Jodie, Tony | D90: C | E90: R | F90: R | G90: 21 | H90: ? | I90: ? | J90: ? | K90: ? | L90: ? | M90: ? | N90: ? | O90: ? | P90: ? | Q90: 231 | R90: Jodie, Tony | S90: C | T90: R | U90: R | V90: 21 | W90: ? | X90: ? | Y90: ? | Z90: ? | AA90: ? | AB90: ? | AC90: ? | AD90: ? | AE90: ? | AF90: ? | AG90: ? | AH90: ? | AI90: =H$1*((-0.000002)*H90^3+0.00032*H90^2+(-0.0021)*H90)+I$1*((-0.000002)*I90^3+0.00032*I90^2+(-0.0021)*I90)+J$1*((-0.000002)*J90^3+0.00032*J90^2+(-0.0021)*J90)+K$1*((-0.000002)*K90^3+0.00032*K90^2+(-0.0021)*K90)+L$1*((-0.000002)*L90^3+0.00032*L90^2+(-0.0021)*L90) -> #VALUE! | AJ90: =M$1*((-0.000002)*M90^3+0.00032*M90^2+(-0.0021)*M90)+N$1*((-0.000002)*N90^3+0.00032*N90^2+(-0.0021)*N90)+O$1*((-0.000002)*O90^3+0.00032*O90^2+(-0.0021)*O90) -> #VALUE! | AK90: =IF(AA90<50,W$1*((-0.000002)*W90^3+0.00032*W90^2+(-0.0021)*W90)+X$1*((-0.000002)*X90^3+0.00032*X90^2+(-0.0021)*X90)+Y$1*((-0.000002)*Y90^3+0.00032*Y90^2+(-0.0021)*Y90)+Z$1*((-0.000002)*Z90^3+0.00032*Z90^2+(-0.0021)*Z90),X$2*((-0.000002)*X90^3+0.00032*X90^2+(-0.0021)*X90)+Y$2*((-0.000002)*Y90^3+0.00032*Y90^2+(-0.0021)*Y90)+Z$2*((-0.000002)*Z90^3+0.00032*Z90^2+(-0.0021)*Z90)+AA$2*((-0.000002)*AA90^3+0.00032*AA90^2+(-0.0021)*AA90)) -> #VALUE! | AL90: =AB$1*((-0.000002)*AB90^3+0.00032*AB90^2+(-0.0021)*AB90)+AC$1*((-0.000002)*AC90^3+0.00032*AC90^2+(-0.0021)*AC90) -> #VALUE! | AM90: =AD$1*((-0.000002)*AD90^3+0.00032*AD90^2+(-0.0021)*AD90)+AE$1*((-0.000002)*AE90^3+0.00032*AE90^2+(-0.0021)*AE90)+AF$1*((-0.000002)*AF90^3+0.00032*AF90^2+(-0.0021)*AF90)+AG$1*((-0.000002)*AG90^3+0.00032*AG90^2+(-0.0021)*AG90) -> #VALUE!
A91: =IFERROR((AI91*AI$3+AJ91*AJ$3+AK91*AK$3+AL91*AL$3+AM91*AM$3)*100/(AI$5*AI$3+AJ$5*AJ$3+AK$5*AK$3+AL$5*AL$3+AM$5*AM$3),0) -> 0 | B91: 232 | C91: Hernandez, Ezdra | D91: C | E91: R | F91: R | G91: 19 | H91: ? | I91: ? | J91: ? | K91: ? | L91: ? | M91: ? | N91: ? | O91: ? | P91: ? | Q91: 232 | R91: Hernandez, Ezdra | S91: C | T91: R | U91: R | V91: 19 | W91: ? | X91: ? | Y91: ? | Z91: ? | AA91: ? | AB91: ? | AC91: ? | AD91: ? | AE91: ? | AF91: ? | AG91: ? | AH91: ? | AI91: =H$1*((-0.000002)*H91^3+0.00032*H91^2+(-0.0021)*H91)+I$1*((-0.000002)*I91^3+0.00032*I91^2+(-0.0021)*I91)+J$1*((-0.000002)*J91^3+0.00032*J91^2+(-0.0021)*J91)+K$1*((-0.000002)*K91^3+0.00032*K91^2+(-0.0021)*K91)+L$1*((-0.000002)*L91^3+0.00032*L91^2+(-0.0021)*L91) -> #VALUE! | AJ91: =M$1*((-0.000002)*M91^3+0.00032*M91^2+(-0.0021)*M91)+N$1*((-0.000002)*N91^3+0.00032*N91^2+(-0.0021)*N91)+O$1*((-0.000002)*O91^3+0.00032*O91^2+(-0.0021)*O91) -> #VALUE! | AK91: =IF(AA91<50,W$1*((-0.000002)*W91^3+0.00032*W91^2+(-0.0021)*W91)+X$1*((-0.000002)*X91^3+0.00032*X91^2+(-0.0021)*X91)+Y$1*((-0.000002)*Y91^3+0.00032*Y91^2+(-0.0021)*Y91)+Z$1*((-0.000002)*Z91^3+0.00032*Z91^2+(-0.0021)*Z91),X$2*((-0.000002)*X91^3+0.00032*X91^2+(-0.0021)*X91)+Y$2*((-0.000002)*Y91^3+0.00032*Y91^2+(-0.0021)*Y91)+Z$2*((-0.000002)*Z91^3+0.00032*Z91^2+(-0.0021)*Z91)+AA$2*((-0.000002)*AA91^3+0.00032*AA91^2+(-0.0021)*AA91)) -> #VALUE! | AL91: =AB$1*((-0.000002)*AB91^3+0.00032*AB91^2+(-0.0021)*AB91)+AC$1*((-0.000002)*AC91^3+0.00032*AC91^2+(-0.0021)*AC91) -> #VALUE! | AM91: =AD$1*((-0.000002)*AD91^3+0.00032*AD91^2+(-0.0021)*AD91)+AE$1*((-0.000002)*AE91^3+0.00032*AE91^2+(-0.0021)*AE91)+AF$1*((-0.000002)*AF91^3+0.00032*AF91^2+(-0.0021)*AF91)+AG$1*((-0.000002)*AG91^3+0.00032*AG91^2+(-0.0021)*AG91) -> #VALUE!
A92: =IFERROR((AI92*AI$3+AJ92*AJ$3+AK92*AK$3+AL92*AL$3+AM92*AM$3)*100/(AI$5*AI$3+AJ$5*AJ$3+AK$5*AK$3+AL$5*AL$3+AM$5*AM$3),0) -> 0 | B92: 233 | C92: Burks, Gill | D92: C | E92: R | F92: R | G92: 19 | H92: ? | I92: ? | J92: ? | K92: ? | L92: ? | M92: ? | N92: ? | O92: ? | P92: ? | Q92: 233 | R92: Burks, Gill | S92: C | T92: R | U92: R | V92: 19 | W92: ? | X92: ? | Y92: ? | Z92: ? | AA92: ? | AB92: ? | AC92: ? | AD92: ? | AE92: ? | AF92: ? | AG92: ? | AH92: ? | AI92: =H$1*((-0.000002)*H92^3+0.00032*H92^2+(-0.0021)*H92)+I$1*((-0.000002)*I92^3+0.00032*I92^2+(-0.0021)*I92)+J$1*((-0.000002)*J92^3+0.00032*J92^2+(-0.0021)*J92)+K$1*((-0.000002)*K92^3+0.00032*K92^2+(-0.0021)*K92)+L$1*((-0.000002)*L92^3+0.00032*L92^2+(-0.0021)*L92) -> #VALUE! | AJ92: =M$1*((-0.000002)*M92^3+0.00032*M92^2+(-0.0021)*M92)+N$1*((-0.000002)*N92^3+0.00032*N92^2+(-0.0021)*N92)+O$1*((-0.000002)*O92^3+0.00032*O92^2+(-0.0021)*O92) -> #VALUE! | AK92: =IF(AA92<50,W$1*((-0.000002)*W92^3+0.00032*W92^2+(-0.0021)*W92)+X$1*((-0.000002)*X92^3+0.00032*X92^2+(-0.0021)*X92)+Y$1*((-0.000002)*Y92^3+0.00032*Y92^2+(-0.0021)*Y92)+Z$1*((-0.000002)*Z92^3+0.00032*Z92^2+(-0.0021)*Z92),X$2*((-0.000002)*X92^3+0.00032*X92^2+(-0.0021)*X92)+Y$2*((-0.000002)*Y92^3+0.00032*Y92^2+(-0.0021)*Y92)+Z$2*((-0.000002)*Z92^3+0.00032*Z92^2+(-0.0021)*Z92)+AA$2*((-0.000002)*AA92^3+0.00032*AA92^2+(-0.0021)*AA92)) -> #VALUE! | AL92: =AB$1*((-0.000002)*AB92^3+0.00032*AB92^2+(-0.0021)*AB92)+AC$1*((-0.000002)*AC92^3+0.00032*AC92^2+(-0.0021)*AC92) -> #VALUE! | AM92: =AD$1*((-0.000002)*AD92^3+0.00032*AD92^2+(-0.0021)*AD92)+AE$1*((-0.000002)*AE92^3+0.00032*AE92^2+(-0.0021)*AE92)+AF$1*((-0.000002)*AF92^3+0.00032*AF92^2+(-0.0021)*AF92)+AG$1*((-0.000002)*AG92^3+0.00032*AG92^2+(-0.0021)*AG92) -> #VALUE!
A93: =IFERROR((AI93*AI$3+AJ93*AJ$3+AK93*AK$3+AL93*AL$3+AM93*AM$3)*100/(AI$5*AI$3+AJ$5*AJ$3+AK$5*AK$3+AL$5*AL$3+AM$5*AM$3),0) -> 0 | B93: 234 | C93: King, Roger | D93: C | E93: R | F93: R | G93: 20 | H93: ? | I93: ? | J93: ? | K93: ? | L93: ? | M93: ? | N93: ? | O93: ? | P93: ? | Q93: 234 | R93: King, Roger | S93: C | T93: R | U93: R | V93: 20 | W93: ? | X93: ? | Y93: ? | Z93: ? | AA93: ? | AB93: ? | AC93: ? | AD93: ? | AE93: ? | AF93: ? | AG93: ? | AH93: ? | AI93: =H$1*((-0.000002)*H93^3+0.00032*H93^2+(-0.0021)*H93)+I$1*((-0.000002)*I93^3+0.00032*I93^2+(-0.0021)*I93)+J$1*((-0.000002)*J93^3+0.00032*J93^2+(-0.0021)*J93)+K$1*((-0.000002)*K93^3+0.00032*K93^2+(-0.0021)*K93)+L$1*((-0.000002)*L93^3+0.00032*L93^2+(-0.0021)*L93) -> #VALUE! | AJ93: =M$1*((-0.000002)*M93^3+0.00032*M93^2+(-0.0021)*M93)+N$1*((-0.000002)*N93^3+0.00032*N93^2+(-0.0021)*N93)+O$1*((-0.000002)*O93^3+0.00032*O93^2+(-0.0021)*O93) -> #VALUE! | AK93: =IF(AA93<50,W$1*((-0.000002)*W93^3+0.00032*W93^2+(-0.0021)*W93)+X$1*((-0.000002)*X93^3+0.00032*X93^2+(-0.0021)*X93)+Y$1*((-0.000002)*Y93^3+0.00032*Y93^2+(-0.0021)*Y93)+Z$1*((-0.000002)*Z93^3+0.00032*Z93^2+(-0.0021)*Z93),X$2*((-0.000002)*X93^3+0.00032*X93^2+(-0.0021)*X93)+Y$2*((-0.000002)*Y93^3+0.00032*Y93^2+(-0.0021)*Y93)+Z$2*((-0.000002)*Z93^3+0.00032*Z93^2+(-0.0021)*Z93)+AA$2*((-0.000002)*AA93^3+0.00032*AA93^2+(-0.0021)*AA93)) -> #VALUE! | AL93: =AB$1*((-0.000002)*AB93^3+0.00032*AB93^2+(-0.0021)*AB93)+AC$1*((-0.000002)*AC93^3+0.00032*AC93^2+(-0.0021)*AC93) -> #VALUE! | AM93: =AD$1*((-0.000002)*AD93^3+0.00032*AD93^2+(-0.0021)*AD93)+AE$1*((-0.000002)*AE93^3+0.00032*AE93^2+(-0.0021)*AE93)+AF$1*((-0.000002)*AF93^3+0.00032*AF93^2+(-0.0021)*AF93)+AG$1*((-0.000002)*AG93^3+0.00032*AG93^2+(-0.0021)*AG93) -> #VALUE!
A94: =IFERROR((AI94*AI$3+AJ94*AJ$3+AK94*AK$3+AL94*AL$3+AM94*AM$3)*100/(AI$5*AI$3+AJ$5*AJ$3+AK$5*AK$3+AL$5*AL$3+AM$5*AM$3),0) -> 0 | B94: 235 | C94: Riley, Clay | D94: C | E94: R | F94: R | G94: 21 | H94: ? | I94: ? | J94: ? | K94: ? | L94: ? | M94: ? | N94: ? | O94: ? | P94: ? | Q94: 235 | R94: Riley, Clay | S94: C | T94: R | U94: R | V94: 21 | W94: ? | X94: ? | Y94: ? | Z94: ? | AA94: ? | AB94: ? | AC94: ? | AD94: ? | AE94: ? | AF94: ? | AG94: ? | AH94: ? | AI94: =H$1*((-0.000002)*H94^3+0.00032*H94^2+(-0.0021)*H94)+I$1*((-0.000002)*I94^3+0.00032*I94^2+(-0.0021)*I94)+J$1*((-0.000002)*J94^3+0.00032*J94^2+(-0.0021)*J94)+K$1*((-0.000002)*K94^3+0.00032*K94^2+(-0.0021)*K94)+L$1*((-0.000002)*L94^3+0.00032*L94^2+(-0.0021)*L94) -> #VALUE! | AJ94: =M$1*((-0.000002)*M94^3+0.00032*M94^2+(-0.0021)*M94)+N$1*((-0.000002)*N94^3+0.00032*N94^2+(-0.0021)*N94)+O$1*((-0.000002)*O94^3+0.00032*O94^2+(-0.0021)*O94) -> #VALUE! | AK94: =IF(AA94<50,W$1*((-0.000002)*W94^3+0.00032*W94^2+(-0.0021)*W94)+X$1*((-0.000002)*X94^3+0.00032*X94^2+(-0.0021)*X94)+Y$1*((-0.000002)*Y94^3+0.00032*Y94^2+(-0.0021)*Y94)+Z$1*((-0.000002)*Z94^3+0.00032*Z94^2+(-0.0021)*Z94),X$2*((-0.000002)*X94^3+0.00032*X94^2+(-0.0021)*X94)+Y$2*((-0.000002)*Y94^3+0.00032*Y94^2+(-0.0021)*Y94)+Z$2*((-0.000002)*Z94^3+0.00032*Z94^2+(-0.0021)*Z94)+AA$2*((-0.000002)*AA94^3+0.00032*AA94^2+(-0.0021)*AA94)) -> #VALUE! | AL94: =AB$1*((-0.000002)*AB94^3+0.00032*AB94^2+(-0.0021)*AB94)+AC$1*((-0.000002)*AC94^3+0.00032*AC94^2+(-0.0021)*AC94) -> #VALUE! | AM94: =AD$1*((-0.000002)*AD94^3+0.00032*AD94^2+(-0.0021)*AD94)+AE$1*((-0.000002)*AE94^3+0.00032*AE94^2+(-0.0021)*AE94)+AF$1*((-0.000002)*AF94^3+0.00032*AF94^2+(-0.0021)*AF94)+AG$1*((-0.000002)*AG94^3+0.00032*AG94^2+(-0.0021)*AG94) -> #VALUE!
A95: =IFERROR((AI95*AI$3+AJ95*AJ$3+AK95*AK$3+AL95*AL$3+AM95*AM$3)*100/(AI$5*AI$3+AJ$5*AJ$3+AK$5*AK$3+AL$5*AL$3+AM$5*AM$3),0) -> 0 | B95: 236 | C95: Mendoza, Stefen | D95: C | E95: R | F95: R | G95: 19 | H95: ? | I95: ? | J95: ? | K95: ? | L95: ? | M95: ? | N95: ? | O95: ? | P95: ? | Q95: 236 | R95: Mendoza, Stefen | S95: C | T95: R | U95: R | V95: 19 | W95: ? | X95: ? | Y95: ? | Z95: ? | AA95: ? | AB95: ? | AC95: ? | AD95: ? | AE95: ? | AF95: ? | AG95: ? | AH95: ? | AI95: =H$1*((-0.000002)*H95^3+0.00032*H95^2+(-0.0021)*H95)+I$1*((-0.000002)*I95^3+0.00032*I95^2+(-0.0021)*I95)+J$1*((-0.000002)*J95^3+0.00032*J95^2+(-0.0021)*J95)+K$1*((-0.000002)*K95^3+0.00032*K95^2+(-0.0021)*K95)+L$1*((-0.000002)*L95^3+0.00032*L95^2+(-0.0021)*L95) -> #VALUE! | AJ95: =M$1*((-0.000002)*M95^3+0.00032*M95^2+(-0.0021)*M95)+N$1*((-0.000002)*N95^3+0.00032*N95^2+(-0.0021)*N95)+O$1*((-0.000002)*O95^3+0.00032*O95^2+(-0.0021)*O95) -> #VALUE! | AK95: =IF(AA95<50,W$1*((-0.000002)*W95^3+0.00032*W95^2+(-0.0021)*W95)+X$1*((-0.000002)*X95^3+0.00032*X95^2+(-0.0021)*X95)+Y$1*((-0.000002)*Y95^3+0.00032*Y95^2+(-0.0021)*Y95)+Z$1*((-0.000002)*Z95^3+0.00032*Z95^2+(-0.0021)*Z95),X$2*((-0.000002)*X95^3+0.00032*X95^2+(-0.0021)*X95)+Y$2*((-0.000002)*Y95^3+0.00032*Y95^2+(-0.0021)*Y95)+Z$2*((-0.000002)*Z95^3+0.00032*Z95^2+(-0.0021)*Z95)+AA$2*((-0.000002)*AA95^3+0.00032*AA95^2+(-0.0021)*AA95)) -> #VALUE! | AL95: =AB$1*((-0.000002)*AB95^3+0.00032*AB95^2+(-0.0021)*AB95)+AC$1*((-0.000002)*AC95^3+0.00032*AC95^2+(-0.0021)*AC95) -> #VALUE! | AM95: =AD$1*((-0.000002)*AD95^3+0.00032*AD95^2+(-0.0021)*AD95)+AE$1*((-0.000002)*AE95^3+0.00032*AE95^2+(-0.0021)*AE95)+AF$1*((-0.000002)*AF95^3+0.00032*AF95^2+(-0.0021)*AF95)+AG$1*((-0.000002)*AG95^3+0.00032*AG95^2+(-0.0021)*AG95) -> #VALUE!
A96: =IFERROR((AI96*AI$3+AJ96*AJ$3+AK96*AK$3+AL96*AL$3+AM96*AM$3)*100/(AI$5*AI$3+AJ$5*AJ$3+AK$5*AK$3+AL$5*AL$3+AM$5*AM$3),0) -> 0 | B96: 237 | C96: Johnson, Wilkin | D96: C | E96: L | F96: R | G96: 18 | H96: ? | I96: ? | J96: ? | K96: ? | L96: ? | M96: ? | N96: ? | O96: ? | P96: ? | Q96: 237 | R96: Johnson, Wilkin | S96: C | T96: L | U96: R | V96: 18 | W96: ? | X96: ? | Y96: ? | Z96: ? | AA96: ? | AB96: ? | AC96: ? | AD96: ? | AE96: ? | AF96: ? | AG96: ? | AH96: ? | AI96: =H$1*((-0.000002)*H96^3+0.00032*H96^2+(-0.0021)*H96)+I$1*((-0.000002)*I96^3+0.00032*I96^2+(-0.0021)*I96)+J$1*((-0.000002)*J96^3+0.00032*J96^2+(-0.0021)*J96)+K$1*((-0.000002)*K96^3+0.00032*K96^2+(-0.0021)*K96)+L$1*((-0.000002)*L96^3+0.00032*L96^2+(-0.0021)*L96) -> #VALUE! | AJ96: =M$1*((-0.000002)*M96^3+0.00032*M96^2+(-0.0021)*M96)+N$1*((-0.000002)*N96^3+0.00032*N96^2+(-0.0021)*N96)+O$1*((-0.000002)*O96^3+0.00032*O96^2+(-0.0021)*O96) -> #VALUE! | AK96: =IF(AA96<50,W$1*((-0.000002)*W96^3+0.00032*W96^2+(-0.0021)*W96)+X$1*((-0.000002)*X96^3+0.00032*X96^2+(-0.0021)*X96)+Y$1*((-0.000002)*Y96^3+0.00032*Y96^2+(-0.0021)*Y96)+Z$1*((-0.000002)*Z96^3+0.00032*Z96^2+(-0.0021)*Z96),X$2*((-0.000002)*X96^3+0.00032*X96^2+(-0.0021)*X96)+Y$2*((-0.000002)*Y96^3+0.00032*Y96^2+(-0.0021)*Y96)+Z$2*((-0.000002)*Z96^3+0.00032*Z96^2+(-0.0021)*Z96)+AA$2*((-0.000002)*AA96^3+0.00032*AA96^2+(-0.0021)*AA96)) -> #VALUE! | AL96: =AB$1*((-0.000002)*AB96^3+0.00032*AB96^2+(-0.0021)*AB96)+AC$1*((-0.000002)*AC96^3+0.00032*AC96^2+(-0.0021)*AC96) -> #VALUE! | AM96: =AD$1*((-0.000002)*AD96^3+0.00032*AD96^2+(-0.0021)*AD96)+AE$1*((-0.000002)*AE96^3+0.00032*AE96^2+(-0.0021)*AE96)+AF$1*((-0.000002)*AF96^3+0.00032*AF96^2+(-0.0021)*AF96)+AG$1*((-0.000002)*AG96^3+0.00032*AG96^2+(-0.0021)*AG96) -> #VALUE!
A97: =IFERROR((AI97*AI$3+AJ97*AJ$3+AK97*AK$3+AL97*AL$3+AM97*AM$3)*100/(AI$5*AI$3+AJ$5*AJ$3+AK$5*AK$3+AL$5*AL$3+AM$5*AM$3),0) -> 0 | B97: 238 | C97: Crespo, Jose | D97: C | E97: R | F97: R | G97: 18 | H97: ? | I97: ? | J97: ? | K97: ? | L97: ? | M97: ? | N97: ? | O97: ? | P97: ? | Q97: 238 | R97: Crespo, Jose | S97: C | T97: R | U97: R | V97: 18 | W97: ? | X97: ? | Y97: ? | Z97: ? | AA97: ? | AB97: ? | AC97: ? | AD97: ? | AE97: ? | AF97: ? | AG97: ? | AH97: ? | AI97: =H$1*((-0.000002)*H97^3+0.00032*H97^2+(-0.0021)*H97)+I$1*((-0.000002)*I97^3+0.00032*I97^2+(-0.0021)*I97)+J$1*((-0.000002)*J97^3+0.00032*J97^2+(-0.0021)*J97)+K$1*((-0.000002)*K97^3+0.00032*K97^2+(-0.0021)*K97)+L$1*((-0.000002)*L97^3+0.00032*L97^2+(-0.0021)*L97) -> #VALUE! | AJ97: =M$1*((-0.000002)*M97^3+0.00032*M97^2+(-0.0021)*M97)+N$1*((-0.000002)*N97^3+0.00032*N97^2+(-0.0021)*N97)+O$1*((-0.000002)*O97^3+0.00032*O97^2+(-0.0021)*O97) -> #VALUE! | AK97: =IF(AA97<50,W$1*((-0.000002)*W97^3+0.00032*W97^2+(-0.0021)*W97)+X$1*((-0.000002)*X97^3+0.00032*X97^2+(-0.0021)*X97)+Y$1*((-0.000002)*Y97^3+0.00032*Y97^2+(-0.0021)*Y97)+Z$1*((-0.000002)*Z97^3+0.00032*Z97^2+(-0.0021)*Z97),X$2*((-0.000002)*X97^3+0.00032*X97^2+(-0.0021)*X97)+Y$2*((-0.000002)*Y97^3+0.00032*Y97^2+(-0.0021)*Y97)+Z$2*((-0.000002)*Z97^3+0.00032*Z97^2+(-0.0021)*Z97)+AA$2*((-0.000002)*AA97^3+0.00032*AA97^2+(-0.0021)*AA97)) -> #VALUE! | AL97: =AB$1*((-0.000002)*AB97^3+0.00032*AB97^2+(-0.0021)*AB97)+AC$1*((-0.000002)*AC97^3+0.00032*AC97^2+(-0.0021)*AC97) -> #VALUE! | AM97: =AD$1*((-0.000002)*AD97^3+0.00032*AD97^2+(-0.0021)*AD97)+AE$1*((-0.000002)*AE97^3+0.00032*AE97^2+(-0.0021)*AE97)+AF$1*((-0.000002)*AF97^3+0.00032*AF97^2+(-0.0021)*AF97)+AG$1*((-0.000002)*AG97^3+0.00032*AG97^2+(-0.0021)*AG97) -> #VALUE!
... A168: =IFERROR((AI168*AI$3+AJ168*AJ$3+AK168*AK$3+AL168*AL$3+AM168*AM$3)*100/(AI$5*AI$3+AJ$5*AJ$3+AK$5*AK$3+AL$5*AL$3+AM$5*AM$3),0) -> 0 | B168: 309 | C168: Accardo, Einar | D168: RF | E168: R | F168: R | G168: 18 | H168: ? | I168: ? | J168: ? | K168: ? | L168: ? | M168: ? | N168: ? | O168: ? | P168: ? | Q168: 309 | R168: Accardo, Einar | S168: RF | T168: R | U168: R | V168: 18 | W168: ? | X168: ? | Y168: ? | Z168: ? | AA168: ? | AB168: ? | AC168: ? | AD168: ? | AE168: ? | AF168: ? | AG168: ? | AH168: ? | AI168: =H$1*((-0.000002)*H168^3+0.00032*H168^2+(-0.0021)*H168)+I$1*((-0.000002)*I168^3+0.00032*I168^2+(-0.0021)*I168)+J$1*((-0.000002)*J168^3+0.00032*J168^2+(-0.0021)*J168)+K$1*((-0.000002)*K168^3+0.00032*K168^2+(-0.0021)*K168)+L$1*((-0.000002)*L168^3+0.00032*L168^2+(-0.0021)*L168) -> #VALUE! | AJ168: =M$1*((-0.000002)*M168^3+0.00032*M168^2+(-0.0021)*M168)+N$1*((-0.000002)*N168^3+0.00032*N168^2+(-0.0021)*N168)+O$1*((-0.000002)*O168^3+0.00032*O168^2+(-0.0021)*O168) -> #VALUE! | AK168: =IF(AA168<50,W$1*((-0.000002)*W168^3+0.00032*W168^2+(-0.0021)*W168)+X$1*((-0.000002)*X168^3+0.00032*X168^2+(-0.0021)*X168)+Y$1*((-0.000002)*Y168^3+0.00032*Y168^2+(-0.0021)*Y168)+Z$1*((-0.000002)*Z168^3+0.00032*Z168^2+(-0.0021)*Z168),X$2*((-0.000002)*X168^3+0.00032*X168^2+(-0.0021)*X168)+Y$2*((-0.000002)*Y168^3+0.00032*Y168^2+(-0.0021)*Y168)+Z$2*((-0.000002)*Z168^3+0.00032*Z168^2+(-0.0021)*Z168)+AA$2*((-0.000002)*AA168^3+0.00032*AA168^2+(-0.0021)*AA168)) -> #VALUE! | AL168: =AB$1*((-0.000002)*AB168^3+0.00032*AB168^2+(-0.0021)*AB168)+AC$1*((-0.000002)*AC168^3+0.00032*AC168^2+(-0.0021)*AC168) -> #VALUE! | AM168: =AD$1*((-0.000002)*AD168^3+0.00032*AD168^2+(-0.0021)*AD168)+AE$1*((-0.000002)*AE168^3+0.00032*AE168^2+(-0.0021)*AE168)+AF$1*((-0.000002)*AF168^3+0.00032*AF168^2+(-0.0021)*AF168)+AG$1*((-0.000002)*AG168^3+0.00032*AG168^2+(-0.0021)*AG168) -> #VALUE!
A169: =IFERROR((AI169*AI$3+AJ169*AJ$3+AK169*AK$3+AL169*AL$3+AM169*AM$3)*100/(AI$5*AI$3+AJ$5*AJ$3+AK$5*AK$3+AL$5*AL$3+AM$5*AM$3),0) -> 0 | B169: 310 | C169: Ryal, Dennys | D169: ? | E169: ? | F169: ? | G169: ? | H169: ? | I169: ? | J169: ? | K169: ? | L169: ? | M169: ? | N169: ? | O169: ? | P169: ? | Q169: 310 | R169: Ryal, Dennys | S169: ? | T169: ? | U169: ? | V169: ? | W169: ? | X169: ? | Y169: ? | Z169: ? | AA169: ? | AB169: ? | AC169: ? | AD169: ? | AE169: ? | AF169: ? | AG169: ? | AH169: ? | AI169: =H$1*((-0.000002)*H169^3+0.00032*H169^2+(-0.0021)*H169)+I$1*((-0.000002)*I169^3+0.00032*I169^2+(-0.0021)*I169)+J$1*((-0.000002)*J169^3+0.00032*J169^2+(-0.0021)*J169)+K$1*((-0.000002)*K169^3+0.00032*K169^2+(-0.0021)*K169)+L$1*((-0.000002)*L169^3+0.00032*L169^2+(-0.0021)*L169) -> #VALUE! | AJ169: =M$1*((-0.000002)*M169^3+0.00032*M169^2+(-0.0021)*M169)+N$1*((-0.000002)*N169^3+0.00032*N169^2+(-0.0021)*N169)+O$1*((-0.000002)*O169^3+0.00032*O169^2+(-0.0021)*O169) -> #VALUE! | AK169: =IF(AA169<50,W$1*((-0.000002)*W169^3+0.00032*W169^2+(-0.0021)*W169)+X$1*((-0.000002)*X169^3+0.00032*X169^2+(-0.0021)*X169)+Y$1*((-0.000002)*Y169^3+0.00032*Y169^2+(-0.0021)*Y169)+Z$1*((-0.000002)*Z169^3+0.00032*Z169^2+(-0.0021)*Z169),X$2*((-0.000002)*X169^3+0.00032*X169^2+(-0.0021)*X169)+Y$2*((-0.000002)*Y169^3+0.00032*Y169^2+(-0.0021)*Y169)+Z$2*((-0.000002)*Z169^3+0.00032*Z169^2+(-0.0021)*Z169)+AA$2*((-0.000002)*AA169^3+0.00032*AA169^2+(-0.0021)*AA169)) -> #VALUE! | AL169: =AB$1*((-0.000002)*AB169^3+0.00032*AB169^2+(-0.0021)*AB169)+AC$1*((-0.000002)*AC169^3+0.00032*AC169^2+(-0.0021)*AC169) -> #VALUE! | AM169: =AD$1*((-0.000002)*AD169^3+0.00032*AD169^2+(-0.0021)*AD169)+AE$1*((-0.000002)*AE169^3+0.00032*AE169^2+(-0.0021)*AE169)+AF$1*((-0.000002)*AF169^3+0.00032*AF169^2+(-0.0021)*AF169)+AG$1*((-0.000002)*AG169^3+0.00032*AG169^2+(-0.0021)*AG169) -> #VALUE!
A170: =IFERROR((AI170*AI$3+AJ170*AJ$3+AK170*AK$3+AL170*AL$3+AM170*AM$3)*100/(AI$5*AI$3+AJ$5*AJ$3+AK$5*AK$3+AL$5*AL$3+AM$5*AM$3),0) -> 0 | B170: 311 | C170: Lange, Ronald | D170: ? | E170: ? | F170: ? | G170: ? | H170: ? | I170: ? | J170: ? | K170: ? | L170: ? | M170: ? | N170: ? | O170: ? | P170: ? | Q170: 311 | R170: Lange, Ronald | S170: ? | T170: ? | U170: ? | V170: ? | W170: ? | X170: ? | Y170: ? | Z170: ? | AA170: ? | AB170: ? | AC170: ? | AD170: ? | AE170: ? | AF170: ? | AG170: ? | AH170: ? | AI170: =H$1*((-0.000002)*H170^3+0.00032*H170^2+(-0.0021)*H170)+I$1*((-0.000002)*I170^3+0.00032*I170^2+(-0.0021)*I170)+J$1*((-0.000002)*J170^3+0.00032*J170^2+(-0.0021)*J170)+K$1*((-0.000002)*K170^3+0.00032*K170^2+(-0.0021)*K170)+L$1*((-0.000002)*L170^3+0.00032*L170^2+(-0.0021)*L170) -> #VALUE! | AJ170: =M$1*((-0.000002)*M170^3+0.00032*M170^2+(-0.0021)*M170)+N$1*((-0.000002)*N170^3+0.00032*N170^2+(-0.0021)*N170)+O$1*((-0.000002)*O170^3+0.00032*O170^2+(-0.0021)*O170) -> #VALUE! | AK170: =IF(AA170<50,W$1*((-0.000002)*W170^3+0.00032*W170^2+(-0.0021)*W170)+X$1*((-0.000002)*X170^3+0.00032*X170^2+(-0.0021)*X170)+Y$1*((-0.000002)*Y170^3+0.00032*Y170^2+(-0.0021)*Y170)+Z$1*((-0.000002)*Z170^3+0.00032*Z170^2+(-0.0021)*Z170),X$2*((-0.000002)*X170^3+0.00032*X170^2+(-0.0021)*X170)+Y$2*((-0.000002)*Y170^3+0.00032*Y170^2+(-0.0021)*Y170)+Z$2*((-0.000002)*Z170^3+0.00032*Z170^2+(-0.0021)*Z170)+AA$2*((-0.000002)*AA170^3+0.00032*AA170^2+(-0.0021)*AA170)) -> #VALUE! | AL170: =AB$1*((-0.000002)*AB170^3+0.00032*AB170^2+(-0.0021)*AB170)+AC$1*((-0.000002)*AC170^3+0.00032*AC170^2+(-0.0021)*AC170) -> #VALUE! | AM170: =AD$1*((-0.000002)*AD170^3+0.00032*AD170^2+(-0.0021)*AD170)+AE$1*((-0.000002)*AE170^3+0.00032*AE170^2+(-0.0021)*AE170)+AF$1*((-0.000002)*AF170^3+0.00032*AF170^2+(-0.0021)*AF170)+AG$1*((-0.000002)*AG170^3+0.00032*AG170^2+(-0.0021)*AG170) -> #VALUE!
A171: =IFERROR((AI171*AI$3+AJ171*AJ$3+AK171*AK$3+AL171*AL$3+AM171*AM$3)*100/(AI$5*AI$3+AJ$5*AJ$3+AK$5*AK$3+AL$5*AL$3+AM$5*AM$3),0) -> 0 | B171: 312 | C171: Sullivan, John | D171: ? | E171: ? | F171: ? | G171: ? | H171: ? | I171: ? | J171: ? | K171: ? | L171: ? | M171: ? | N171: ? | O171: ? | P171: ? | Q171: 312 | R171: Sullivan, John | S171: ? | T171: ? | U171: ? | V171: ? | W171: ? | X171: ? | Y171: ? | Z171: ? | AA171: ? | AB171: ? | AC171: ? | AD171: ? | AE171: ? | AF171: ? | AG171: ? | AH171: ? | AI171: =H$1*((-0.000002)*H171^3+0.00032*H171^2+(-0.0021)*H171)+I$1*((-0.000002)*I171^3+0.00032*I171^2+(-0.0021)*I171)+J$1*((-0.000002)*J171^3+0.00032*J171^2+(-0.0021)*J171)+K$1*((-0.000002)*K171^3+0.00032*K171^2+(-0.0021)*K171)+L$1*((-0.000002)*L171^3+0.00032*L171^2+(-0.0021)*L171) -> #VALUE! | AJ171: =M$1*((-0.000002)*M171^3+0.00032*M171^2+(-0.0021)*M171)+N$1*((-0.000002)*N171^3+0.00032*N171^2+(-0.0021)*N171)+O$1*((-0.000002)*O171^3+0.00032*O171^2+(-0.0021)*O171) -> #VALUE! | AK171: =IF(AA171<50,W$1*((-0.000002)*W171^3+0.00032*W171^2+(-0.0021)*W171)+X$1*((-0.000002)*X171^3+0.00032*X171^2+(-0.0021)*X171)+Y$1*((-0.000002)*Y171^3+0.00032*Y171^2+(-0.0021)*Y171)+Z$1*((-0.000002)*Z171^3+0.00032*Z171^2+(-0.0021)*Z171),X$2*((-0.000002)*X171^3+0.00032*X171^2+(-0.0021)*X171)+Y$2*((-0.000002)*Y171^3+0.00032*Y171^2+(-0.0021)*Y171)+Z$2*((-0.000002)*Z171^3+0.00032*Z171^2+(-0.0021)*Z171)+AA$2*((-0.000002)*AA171^3+0.00032*AA171^2+(-0.0021)*AA171)) -> #VALUE! | AL171: =AB$1*((-0.000002)*AB171^3+0.00032*AB171^2+(-0.0021)*AB171)+AC$1*((-0.000002)*AC171^3+0.00032*AC171^2+(-0.0021)*AC171) -> #VALUE! | AM171: =AD$1*((-0.000002)*AD171^3+0.00032*AD171^2+(-0.0021)*AD171)+AE$1*((-0.000002)*AE171^3+0.00032*AE171^2+(-0.0021)*AE171)+AF$1*((-0.000002)*AF171^3+0.00032*AF171^2+(-0.0021)*AF171)+AG$1*((-0.000002)*AG171^3+0.00032*AG171^2+(-0.0021)*AG171) -> #VALUE!
A172: =IFERROR((AI172*AI$3+AJ172*AJ$3+AK172*AK$3+AL172*AL$3+AM172*AM$3)*100/(AI$5*AI$3+AJ$5*AJ$3+AK$5*AK$3+AL$5*AL$3+AM$5*AM$3),0) -> 0 | B172: 313 | C172: Wengert, Japhet | D172: ? | E172: ? | F172: ? | G172: ? | H172: ? | I172: ? | J172: ? | K172: ? | L172: ? | M172: ? | N172: ? | O172: ? | P172: ? | Q172: 313 | R172: Wengert, Japhet | S172: ? | T172: ? | U172: ? | V172: ? | W172: ? | X172: ? | Y172: ? | Z172: ? | AA172: ? | AB172: ? | AC172: ? | AD172: ? | AE172: ? | AF172: ? | AG172: ? | AH172: ? | AI172: =H$1*((-0.000002)*H172^3+0.00032*H172^2+(-0.0021)*H172)+I$1*((-0.000002)*I172^3+0.00032*I172^2+(-0.0021)*I172)+J$1*((-0.000002)*J172^3+0.00032*J172^2+(-0.0021)*J172)+K$1*((-0.000002)*K172^3+0.00032*K172^2+(-0.0021)*K172)+L$1*((-0.000002)*L172^3+0.00032*L172^2+(-0.0021)*L172) -> #VALUE! | AJ172: =M$1*((-0.000002)*M172^3+0.00032*M172^2+(-0.0021)*M172)+N$1*((-0.000002)*N172^3+0.00032*N172^2+(-0.0021)*N172)+O$1*((-0.000002)*O172^3+0.00032*O172^2+(-0.0021)*O172) -> #VALUE! | AK172: =IF(AA172<50,W$1*((-0.000002)*W172^3+0.00032*W172^2+(-0.0021)*W172)+X$1*((-0.000002)*X172^3+0.00032*X172^2+(-0.0021)*X172)+Y$1*((-0.000002)*Y172^3+0.00032*Y172^2+(-0.0021)*Y172)+Z$1*((-0.000002)*Z172^3+0.00032*Z172^2+(-0.0021)*Z172),X$2*((-0.000002)*X172^3+0.00032*X172^2+(-0.0021)*X172)+Y$2*((-0.000002)*Y172^3+0.00032*Y172^2+(-0.0021)*Y172)+Z$2*((-0.000002)*Z172^3+0.00032*Z172^2+(-0.0021)*Z172)+AA$2*((-0.000002)*AA172^3+0.00032*AA172^2+(-0.0021)*AA172)) -> #VALUE! | AL172: =AB$1*((-0.000002)*AB172^3+0.00032*AB172^2+(-0.0021)*AB172)+AC$1*((-0.000002)*AC172^3+0.00032*AC172^2+(-0.0021)*AC172) -> #VALUE! | AM172: =AD$1*((-0.000002)*AD172^3+0.00032*AD172^2+(-0.0021)*AD172)+AE$1*((-0.000002)*AE172^3+0.00032*AE172^2+(-0.0021)*AE172)+AF$1*((-0.000002)*AF172^3+0.00032*AF172^2+(-0.0021)*AF172)+AG$1*((-0.000002)*AG172^3+0.00032*AG172^2+(-0.0021)*AG172) -> #VALUE!
A173: =IFERROR((AI173*AI$3+AJ173*AJ$3+AK173*AK$3+AL173*AL$3+AM173*AM$3)*100/(AI$5*AI$3+AJ$5*AJ$3+AK$5*AK$3+AL$5*AL$3+AM$5*AM$3),0) -> 0 | B173: 314 | C173: Cash, Shaggy | D173: ? | E173: ? | F173: ? | G173: ? | H173: ? | I173: ? | J173: ? | K173: ? | L173: ? | M173: ? | N173: ? | O173: ? | P173: ? | Q173: 314 | R173: Cash, Shaggy | S173: ? | T173: ? | U173: ? | V173: ? | W173: ? | X173: ? | Y173: ? | Z173: ? | AA173: ? | AB173: ? | AC173: ? | AD173: ? | AE173: ? | AF173: ? | AG173: ? | AH173: ? | AI173: =H$1*((-0.000002)*H173^3+0.00032*H173^2+(-0.0021)*H173)+I$1*((-0.000002)*I173^3+0.00032*I173^2+(-0.0021)*I173)+J$1*((-0.000002)*J173^3+0.00032*J173^2+(-0.0021)*J173)+K$1*((-0.000002)*K173^3+0.00032*K173^2+(-0.0021)*K173)+L$1*((-0.000002)*L173^3+0.00032*L173^2+(-0.0021)*L173) -> #VALUE! | AJ173: =M$1*((-0.000002)*M173^3+0.00032*M173^2+(-0.0021)*M173)+N$1*((-0.000002)*N173^3+0.00032*N173^2+(-0.0021)*N173)+O$1*((-0.000002)*O173^3+0.00032*O173^2+(-0.0021)*O173) -> #VALUE! | AK173: =IF(AA173<50,W$1*((-0.000002)*W173^3+0.00032*W173^2+(-0.0021)*W173)+X$1*((-0.000002)*X173^3+0.00032*X173^2+(-0.0021)*X173)+Y$1*((-0.000002)*Y173^3+0.00032*Y173^2+(-0.0021)*Y173)+Z$1*((-0.000002)*Z173^3+0.00032*Z173^2+(-0.0021)*Z173),X$2*((-0.000002)*X173^3+0.00032*X173^2+(-0.0021)*X173)+Y$2*((-0.000002)*Y173^3+0.00032*Y173^2+(-0.0021)*Y173)+Z$2*((-0.000002)*Z173^3+0.00032*Z173^2+(-0.0021)*Z173)+AA$2*((-0.000002)*AA173^3+0.00032*AA173^2+(-0.0021)*AA173)) -> #VALUE! | AL173: =AB$1*((-0.000002)*AB173^3+0.00032*AB173^2+(-0.0021)*AB173)+AC$1*((-0.000002)*AC173^3+0.00032*AC173^2+(-0.0021)*AC173) -> #VALUE! | AM173: =AD$1*((-0.000002)*AD173^3+0.00032*AD173^2+(-0.0021)*AD173)+AE$1*((-0.000002)*AE173^3+0.00032*AE173^2+(-0.0021)*AE173)+AF$1*((-0.000002)*AF173^3+0.00032*AF173^2+(-0.0021)*AF173)+AG$1*((-0.000002)*AG173^3+0.00032*AG173^2+(-0.0021)*AG173) -> #VALUE!
A174: =IFERROR((AI174*AI$3+AJ174*AJ$3+AK174*AK$3+AL174*AL$3+AM174*AM$3)*100/(AI$5*AI$3+AJ$5*AJ$3+AK$5*AK$3+AL$5*AL$3+AM$5*AM$3),0) -> 0 | B174: 315 | C174: Cannon, Philip | D174: ? | E174: ? | F174: ? | G174: ? | H174: ? | I174: ? | J174: ? | K174: ? | L174: ? | M174: ? | N174: ? | O174: ? | P174: ? | Q174: 315 | R174: Cannon, Philip | S174: ? | T174: ? | U174: ? | V174: ? | W174: ? | X174: ? | Y174: ? | Z174: ? | AA174: ? | AB174: ? | AC174: ? | AD174: ? | AE174: ? | AF174: ? | AG174: ? | AH174: ? | AI174: =H$1*((-0.000002)*H174^3+0.00032*H174^2+(-0.0021)*H174)+I$1*((-0.000002)*I174^3+0.00032*I174^2+(-0.0021)*I174)+J$1*((-0.000002)*J174^3+0.00032*J174^2+(-0.0021)*J174)+K$1*((-0.000002)*K174^3+0.00032*K174^2+(-0.0021)*K174)+L$1*((-0.000002)*L174^3+0.00032*L174^2+(-0.0021)*L174) -> #VALUE! | AJ174: =M$1*((-0.000002)*M174^3+0.00032*M174^2+(-0.0021)*M174)+N$1*((-0.000002)*N174^3+0.00032*N174^2+(-0.0021)*N174)+O$1*((-0.000002)*O174^3+0.00032*O174^2+(-0.0021)*O174) -> #VALUE! | AK174: =IF(AA174<50,W$1*((-0.000002)*W174^3+0.00032*W174^2+(-0.0021)*W174)+X$1*((-0.000002)*X174^3+0.00032*X174^2+(-0.0021)*X174)+Y$1*((-0.000002)*Y174^3+0.00032*Y174^2+(-0.0021)*Y174)+Z$1*((-0.000002)*Z174^3+0.00032*Z174^2+(-0.0021)*Z174),X$2*((-0.000002)*X174^3+0.00032*X174^2+(-0.0021)*X174)+Y$2*((-0.000002)*Y174^3+0.00032*Y174^2+(-0.0021)*Y174)+Z$2*((-0.000002)*Z174^3+0.00032*Z174^2+(-0.0021)*Z174)+AA$2*((-0.000002)*AA174^3+0.00032*AA174^2+(-0.0021)*AA174)) -> #VALUE! | AL174: =AB$1*((-0.000002)*AB174^3+0.00032*AB174^2+(-0.0021)*AB174)+AC$1*((-0.000002)*AC174^3+0.00032*AC174^2+(-0.0021)*AC174) -> #VALUE! | AM174: =AD$1*((-0.000002)*AD174^3+0.00032*AD174^2+(-0.0021)*AD174)+AE$1*((-0.000002)*AE174^3+0.00032*AE174^2+(-0.0021)*AE174)+AF$1*((-0.000002)*AF174^3+0.00032*AF174^2+(-0.0021)*AF174)+AG$1*((-0.000002)*AG174^3+0.00032*AG174^2+(-0.0021)*AG174) -> #VALUE!
